Workbook

Sheet Calendar_View
A1: OL Booking Calendar | I1: At a glance
A2: Excel-first, presentable, and maintainable — the calendar updates from the Bookings sheet and daily quota model. | I2: Approved bookings | K2: =SUM(Daily_Capacity!$F$4:$F$34) -> 0 | M2: =MATCH(B4,Lists!$A$2:$A$13,0) -> 5
I3: Fully booked days | K3: =COUNTIF(Daily_Capacity!$G$4:$G$34,0) -> 0
A4: Month | B4: May | D4: Year | E4: 2026 | I4: Overbooked days | K4: =COUNTIF(Daily_Capacity!$G$4:$G$34,"<0") -> 0
A5: =TEXT(DATE($E$4,$M$2,1),"mmmm yyyy") -> May 2026 | I5: Average utilization | K5: =AVERAGEIF(Daily_Capacity!$H$4:$H$34,">0") -> #DIV/0!
A6: Mon | B6: Tue | C6: Wed | D6: Thu | E6: Fri | F6: Sat | G6: Sun
A7: =IF(MONTH(_Helper!A1)<>$M$2,"",TEXT(_Helper!A1,"d")&CHAR(10)&"Booked "&_Helper!A9&"/"&_Helper!A17&CHAR(10)&IF(_Helper!A25<0,"Over by "&ABS(_Helper!A25),IF(_Helper!A25=0,"Full",_Helper!A25&" left"))) | B7: =IF(MONTH(_Helper!B1)<>$M$2,"",TEXT(_Helper!B1,"d")&CHAR(10)&"Booked "&_Helper!B9&"/"&_Helper!B17&CHAR(10)&IF(_Helper!B25<0,"Over by "&ABS(_Helper!B25),IF(_Helper!B25=0,"Full",_Helper!B25&" left"))) | C7: =IF(MONTH(_Helper!C1)<>$M$2,"",TEXT(_Helper!C1,"d")&CHAR(10)&"Booked "&_Helper!C9&"/"&_Helper!C17&CHAR(10)&IF(_Helper!C25<0,"Over by "&ABS(_Helper!C25),IF(_Helper!C25=0,"Full",_Helper!C25&" left"))) | D7: =IF(MONTH(_Helper!D1)<>$M$2,"",TEXT(_Helper!D1,"d")&CHAR(10)&"Booked "&_Helper!D9&"/"&_Helper!D17&CHAR(10)&IF(_Helper!D25<0,"Over by "&ABS(_Helper!D25),IF(_Helper!D25=0,"Full",_Helper!D25&" left"))) | E7: =IF(MONTH(_Helper!E1)<>$M$2,"",TEXT(_Helper!E1,"d")&CHAR(10)&"Booked "&_Helper!E9&"/"&_Helper!E17&CHAR(10)&IF(_Helper!E25<0,"Over by "&ABS(_Helper!E25),IF(_Helper!E25=0,"Full",_Helper!E25&" left"))) -> 1 Booked 0/6 6 left | F7: =IF(MONTH(_Helper!F1)<>$M$2,"",TEXT(_Helper!F1,"d")&CHAR(10)&"Booked "&_Helper!F9&"/"&_Helper!F17&CHAR(10)&IF(_Helper!F25<0,"Over by "&ABS(_Helper!F25),IF(_Helper!F25=0,"Full",_Helper!F25&" left"))) -> 2 Booked 0/4 4 left | G7: =IF(MONTH(_Helper!G1)<>$M$2,"",TEXT(_Helper!G1,"d")&CHAR(10)&"Booked "&_Helper!G9&"/"&_Helper!G17&CHAR(10)&IF(_Helper!G25<0,"Over by "&ABS(_Helper!G25),IF(_Helper!G25=0,"Full",_Helper!G25&" left"))) -> 3 Booked 0/4 4 left | I7: Legend
A8: =IF(MONTH(_Helper!A2)<>$M$2,"",TEXT(_Helper!A2,"d")&CHAR(10)&"Booked "&_Helper!A10&"/"&_Helper!A18&CHAR(10)&IF(_Helper!A26<0,"Over by "&ABS(_Helper!A26),IF(_Helper!A26=0,"Full",_Helper!A26&" left"))) -> 4 Booked 0/6 6 left | B8: =IF(MONTH(_Helper!B2)<>$M$2,"",TEXT(_Helper!B2,"d")&CHAR(10)&"Booked "&_Helper!B10&"/"&_Helper!B18&CHAR(10)&IF(_Helper!B26<0,"Over by "&ABS(_Helper!B26),IF(_Helper!B26=0,"Full",_Helper!B26&" left"))) -> 5 Booked 0/6 6 left | C8: =IF(MONTH(_Helper!C2)<>$M$2,"",TEXT(_Helper!C2,"d")&CHAR(10)&"Booked "&_Helper!C10&"/"&_Helper!C18&CHAR(10)&IF(_Helper!C26<0,"Over by "&ABS(_Helper!C26),IF(_Helper!C26=0,"Full",_Helper!C26&" left"))) -> 6 Booked 0/6 6 left | D8: =IF(MONTH(_Helper!D2)<>$M$2,"",TEXT(_Helper!D2,"d")&CHAR(10)&"Booked "&_Helper!D10&"/"&_Helper!D18&CHAR(10)&IF(_Helper!D26<0,"Over by "&ABS(_Helper!D26),IF(_Helper!D26=0,"Full",_Helper!D26&" left"))) -> 7 Booked 0/6 6 left | E8: =IF(MONTH(_Helper!E2)<>$M$2,"",TEXT(_Helper!E2,"d")&CHAR(10)&"Booked "&_Helper!E10&"/"&_Helper!E18&CHAR(10)&IF(_Helper!E26<0,"Over by "&ABS(_Helper!E26),IF(_Helper!E26=0,"Full",_Helper!E26&" left"))) -> 8 Booked 0/8 8 left | F8: =IF(MONTH(_Helper!F2)<>$M$2,"",TEXT(_Helper!F2,"d")&CHAR(10)&"Booked "&_Helper!F10&"/"&_Helper!F18&CHAR(10)&IF(_Helper!F26<0,"Over by "&ABS(_Helper!F26),IF(_Helper!F26=0,"Full",_Helper!F26&" left"))) -> 9 Booked 0/4 4 left | G8: =IF(MONTH(_Helper!G2)<>$M$2,"",TEXT(_Helper!G2,"d")&CHAR(10)&"Booked "&_Helper!G10&"/"&_Helper!G18&CHAR(10)&IF(_Helper!G26<0,"Over by "&ABS(_Helper!G26),IF(_Helper!G26=0,"Full",_Helper!G26&" left"))) -> 10 Booked 0/4 4 left | J8: 3+ slots left
A9: =IF(MONTH(_Helper!A3)<>$M$2,"",TEXT(_Helper!A3,"d")&CHAR(10)&"Booked "&_Helper!A11&"/"&_Helper!A19&CHAR(10)&IF(_Helper!A27<0,"Over by "&ABS(_Helper!A27),IF(_Helper!A27=0,"Full",_Helper!A27&" left"))) -> 11 Booked 0/6 6 left | B9: =IF(MONTH(_Helper!B3)<>$M$2,"",TEXT(_Helper!B3,"d")&CHAR(10)&"Booked "&_Helper!B11&"/"&_Helper!B19&CHAR(10)&IF(_Helper!B27<0,"Over by "&ABS(_Helper!B27),IF(_Helper!B27=0,"Full",_Helper!B27&" left"))) -> 12 Booked 0/3 3 left | C9: =IF(MONTH(_Helper!C3)<>$M$2,"",TEXT(_Helper!C3,"d")&CHAR(10)&"Booked "&_Helper!C11&"/"&_Helper!C19&CHAR(10)&IF(_Helper!C27<0,"Over by "&ABS(_Helper!C27),IF(_Helper!C27=0,"Full",_Helper!C27&" left"))) -> 13 Booked 0/6 6 left | D9: =IF(MONTH(_Helper!D3)<>$M$2,"",TEXT(_Helper!D3,"d")&CHAR(10)&"Booked "&_Helper!D11&"/"&_Helper!D19&CHAR(10)&IF(_Helper!D27<0,"Over by "&ABS(_Helper!D27),IF(_Helper!D27=0,"Full",_Helper!D27&" left"))) -> 14 Booked 0/6 6 left | E9: =IF(MONTH(_Helper!E3)<>$M$2,"",TEXT(_Helper!E3,"d")&CHAR(10)&"Booked "&_Helper!E11&"/"&_Helper!E19&CHAR(10)&IF(_Helper!E27<0,"Over by "&ABS(_Helper!E27),IF(_Helper!E27=0,"Full",_Helper!E27&" left"))) -> 15 Booked 0/5 5 left | F9: =IF(MONTH(_Helper!F3)<>$M$2,"",TEXT(_Helper!F3,"d")&CHAR(10)&"Booked "&_Helper!F11&"/"&_Helper!F19&CHAR(10)&IF(_Helper!F27<0,"Over by "&ABS(_Helper!F27),IF(_Helper!F27=0,"Full",_Helper!F27&" left"))) -> 16 Booked 0/4 4 left | G9: =IF(MONTH(_Helper!G3)<>$M$2,"",TEXT(_Helper!G3,"d")&CHAR(10)&"Booked "&_Helper!G11&"/"&_Helper!G19&CHAR(10)&IF(_Helper!G27<0,"Over by "&ABS(_Helper!G27),IF(_Helper!G27=0,"Full",_Helper!G27&" left"))) -> 17 Booked 0/4 4 left | J9: 1–2 slots left
A10: =IF(MONTH(_Helper!A4)<>$M$2,"",TEXT(_Helper!A4,"d")&CHAR(10)&"Booked "&_Helper!A12&"/"&_Helper!A20&CHAR(10)&IF(_Helper!A28<0,"Over by "&ABS(_Helper!A28),IF(_Helper!A28=0,"Full",_Helper!A28&" left"))) -> 18 Booked 0/6 6 left | B10: =IF(MONTH(_Helper!B4)<>$M$2,"",TEXT(_Helper!B4,"d")&CHAR(10)&"Booked "&_Helper!B12&"/"&_Helper!B20&CHAR(10)&IF(_Helper!B28<0,"Over by "&ABS(_Helper!B28),IF(_Helper!B28=0,"Full",_Helper!B28&" left"))) -> 19 Booked 0/6 6 left | C10: =IF(MONTH(_Helper!C4)<>$M$2,"",TEXT(_Helper!C4,"d")&CHAR(10)&"Booked "&_Helper!C12&"/"&_Helper!C20&CHAR(10)&IF(_Helper!C28<0,"Over by "&ABS(_Helper!C28),IF(_Helper!C28=0,"Full",_Helper!C28&" left"))) -> 20 Booked 0/6 6 left | D10: =IF(MONTH(_Helper!D4)<>$M$2,"",TEXT(_Helper!D4,"d")&CHAR(10)&"Booked "&_Helper!D12&"/"&_Helper!D20&CHAR(10)&IF(_Helper!D28<0,"Over by "&ABS(_Helper!D28),IF(_Helper!D28=0,"Full",_Helper!D28&" left"))) -> 21 Booked 0/8 8 left | E10: =IF(MONTH(_Helper!E4)<>$M$2,"",TEXT(_Helper!E4,"d")&CHAR(10)&"Booked "&_Helper!E12&"/"&_Helper!E20&CHAR(10)&IF(_Helper!E28<0,"Over by "&ABS(_Helper!E28),IF(_Helper!E28=0,"Full",_Helper!E28&" left"))) -> 22 Booked 0/6 6 left | F10: =IF(MONTH(_Helper!F4)<>$M$2,"",TEXT(_Helper!F4,"d")&CHAR(10)&"Booked "&_Helper!F12&"/"&_Helper!F20&CHAR(10)&IF(_Helper!F28<0,"Over by "&ABS(_Helper!F28),IF(_Helper!F28=0,"Full",_Helper!F28&" left"))) -> 23 Booked 0/4 4 left | G10: =IF(MONTH(_Helper!G4)<>$M$2,"",TEXT(_Helper!G4,"d")&CHAR(10)&"Booked "&_Helper!G12&"/"&_Helper!G20&CHAR(10)&IF(_Helper!G28<0,"Over by "&ABS(_Helper!G28),IF(_Helper!G28=0,"Full",_Helper!G28&" left"))) -> 24 Booked 0/4 4 left | J10: Full
A11: =IF(MONTH(_Helper!A5)<>$M$2,"",TEXT(_Helper!A5,"d")&CHAR(10)&"Booked "&_Helper!A13&"/"&_Helper!A21&CHAR(10)&IF(_Helper!A29<0,"Over by "&ABS(_Helper!A29),IF(_Helper!A29=0,"Full",_Helper!A29&" left"))) -> 25 Booked 0/6 6 left | B11: =IF(MONTH(_Helper!B5)<>$M$2,"",TEXT(_Helper!B5,"d")&CHAR(10)&"Booked "&_Helper!B13&"/"&_Helper!B21&CHAR(10)&IF(_Helper!B29<0,"Over by "&ABS(_Helper!B29),IF(_Helper!B29=0,"Full",_Helper!B29&" left"))) -> 26 Booked 0/6 6 left | C11: =IF(MONTH(_Helper!C5)<>$M$2,"",TEXT(_Helper!C5,"d")&CHAR(10)&"Booked "&_Helper!C13&"/"&_Helper!C21&CHAR(10)&IF(_Helper!C29<0,"Over by "&ABS(_Helper!C29),IF(_Helper!C29=0,"Full",_Helper!C29&" left"))) -> 27 Booked 0/6 6 left | D11: =IF(MONTH(_Helper!D5)<>$M$2,"",TEXT(_Helper!D5,"d")&CHAR(10)&"Booked "&_Helper!D13&"/"&_Helper!D21&CHAR(10)&IF(_Helper!D29<0,"Over by "&ABS(_Helper!D29),IF(_Helper!D29=0,"Full",_Helper!D29&" left"))) -> 28 Booked 0/5 5 left | E11: =IF(MONTH(_Helper!E5)<>$M$2,"",TEXT(_Helper!E5,"d")&CHAR(10)&"Booked "&_Helper!E13&"/"&_Helper!E21&CHAR(10)&IF(_Helper!E29<0,"Over by "&ABS(_Helper!E29),IF(_Helper!E29=0,"Full",_Helper!E29&" left"))) -> 29 Booked 0/6 6 left | F11: =IF(MONTH(_Helper!F5)<>$M$2,"",TEXT(_Helper!F5,"d")&CHAR(10)&"Booked "&_Helper!F13&"/"&_Helper!F21&CHAR(10)&IF(_Helper!F29<0,"Over by "&ABS(_Helper!F29),IF(_Helper!F29=0,"Full",_Helper!F29&" left"))) -> 30 Booked 0/4 4 left | G11: =IF(MONTH(_Helper!G5)<>$M$2,"",TEXT(_Helper!G5,"d")&CHAR(10)&"Booked "&_Helper!G13&"/"&_Helper!G21&CHAR(10)&IF(_Helper!G29<0,"Over by "&ABS(_Helper!G29),IF(_Helper!G29=0,"Full",_Helper!G29&" left"))) -> 31 Booked 0/4 4 left | J11: Overbooked
A12: =IF(MONTH(_Helper!A6)<>$M$2,"",TEXT(_Helper!A6,"d")&CHAR(10)&"Booked "&_Helper!A14&"/"&_Helper!A22&CHAR(10)&IF(_Helper!A30<0,"Over by "&ABS(_Helper!A30),IF(_Helper!A30=0,"Full",_Helper!A30&" left"))) | B12: =IF(MONTH(_Helper!B6)<>$M$2,"",TEXT(_Helper!B6,"d")&CHAR(10)&"Booked "&_Helper!B14&"/"&_Helper!B22&CHAR(10)&IF(_Helper!B30<0,"Over by "&ABS(_Helper!B30),IF(_Helper!B30=0,"Full",_Helper!B30&" left"))) | C12: =IF(MONTH(_Helper!C6)<>$M$2,"",TEXT(_Helper!C6,"d")&CHAR(10)&"Booked "&_Helper!C14&"/"&_Helper!C22&CHAR(10)&IF(_Helper!C30<0,"Over by "&ABS(_Helper!C30),IF(_Helper!C30=0,"Full",_Helper!C30&" left"))) | D12: =IF(MONTH(_Helper!D6)<>$M$2,"",TEXT(_Helper!D6,"d")&CHAR(10)&"Booked "&_Helper!D14&"/"&_Helper!D22&CHAR(10)&IF(_Helper!D30<0,"Over by "&ABS(_Helper!D30),IF(_Helper!D30=0,"Full",_Helper!D30&" left"))) | E12: =IF(MONTH(_Helper!E6)<>$M$2,"",TEXT(_Helper!E6,"d")&CHAR(10)&"Booked "&_Helper!E14&"/"&_Helper!E22&CHAR(10)&IF(_Helper!E30<0,"Over by "&ABS(_Helper!E30),IF(_Helper!E30=0,"Full",_Helper!E30&" left"))) | F12: =IF(MONTH(_Helper!F6)<>$M$2,"",TEXT(_Helper!F6,"d")&CHAR(10)&"Booked "&_Helper!F14&"/"&_Helper!F22&CHAR(10)&IF(_Helper!F30<0,"Over by "&ABS(_Helper!F30),IF(_Helper!F30=0,"Full",_Helper!F30&" left"))) | G12: =IF(MONTH(_Helper!G6)<>$M$2,"",TEXT(_Helper!G6,"d")&CHAR(10)&"Booked "&_Helper!G14&"/"&_Helper!G22&CHAR(10)&IF(_Helper!G30<0,"Over by "&ABS(_Helper!G30),IF(_Helper!G30=0,"Full",_Helper!G30&" left")))
I13: Tip: keep the UX simple — paste submissions into Bookings, adjust any daily overrides, and use this sheet as the visual front end.

Sheet Daily_Capacity
A1: Daily Capacity Model
A3: Date | B3: Day | C3: Default Quota | D3: Override Quota | E3: Effective Quota | F3: Approved Bookings | G3: Remaining | H3: Utilization | J3: How to use
A4: =DATE(Calendar_View!$E$4,Calendar_View!$M$2,1) -> 46143 | B4: =IF(A4="","",TEXT(A4,"ddd")) -> Fri | C4: =IF(A4="","",IF(WEEKDAY(A4,2)<=5,6,4)) -> 6 | E4: =IF(A4="","",IF(D4<>"",D4,C4)) -> 6 | F4: =IF(A4="","",COUNTIFS(Bookings!$B$2:$B$140,A4,Bookings!$F$2:$F$140,"Approved")) -> 0 | G4: =IF(A4="","",E4-F4) -> 6 | H4: =IF(OR(A4="",E4=0),"",F4/E4) -> 0 | J4: 1 | K4: Paste real form rows into Bookings sheet.
A5: =IF(A4<EOMONTH(DATE(Calendar_View!$E$4,Calendar_View!$M$2,1),0),A4+1,"") -> 46144 | B5: =IF(A5="","",TEXT(A5,"ddd")) -> Sat | C5: =IF(A5="","",IF(WEEKDAY(A5,2)<=5,6,4)) -> 4 | E5: =IF(A5="","",IF(D5<>"",D5,C5)) -> 4 | F5: =IF(A5="","",COUNTIFS(Bookings!$B$2:$B$140,A5,Bookings!$F$2:$F$140,"Approved")) -> 0 | G5: =IF(A5="","",E5-F5) -> 4 | H5: =IF(OR(A5="",E5=0),"",F5/E5) -> 0 | J5: 2 | K5: Edit only Override Quota when capacity changes.
A6: =IF(A5<EOMONTH(DATE(Calendar_View!$E$4,Calendar_View!$M$2,1),0),A5+1,"") -> 46145 | B6: =IF(A6="","",TEXT(A6,"ddd")) -> Sun | C6: =IF(A6="","",IF(WEEKDAY(A6,2)<=5,6,4)) -> 4 | E6: =IF(A6="","",IF(D6<>"",D6,C6)) -> 4 | F6: =IF(A6="","",COUNTIFS(Bookings!$B$2:$B$140,A6,Bookings!$F$2:$F$140,"Approved")) -> 0 | G6: =IF(A6="","",E6-F6) -> 4 | H6: =IF(OR(A6="",E6=0),"",F6/E6) -> 0 | J6: 3 | K6: Calendar_View updates automatically.
A7: =IF(A6<EOMONTH(DATE(Calendar_View!$E$4,Calendar_View!$M$2,1),0),A6+1,"") -> 46146 | B7: =IF(A7="","",TEXT(A7,"ddd")) -> Mon | C7: =IF(A7="","",IF(WEEKDAY(A7,2)<=5,6,4)) -> 6 | E7: =IF(A7="","",IF(D7<>"",D7,C7)) -> 6 | F7: =IF(A7="","",COUNTIFS(Bookings!$B$2:$B$140,A7,Bookings!$F$2:$F$140,"Approved")) -> 0 | G7: =IF(A7="","",E7-F7) -> 6 | H7: =IF(OR(A7="",E7=0),"",F7/E7) -> 0 | J7: 4 | K7: Green = safe, yellow = tight, red = full/overbooked.
A8: =IF(A7<EOMONTH(DATE(Calendar_View!$E$4,Calendar_View!$M$2,1),0),A7+1,"") -> 46147 | B8: =IF(A8="","",TEXT(A8,"ddd")) -> Tue | C8: =IF(A8="","",IF(WEEKDAY(A8,2)<=5,6,4)) -> 6 | E8: =IF(A8="","",IF(D8<>"",D8,C8)) -> 6 | F8: =IF(A8="","",COUNTIFS(Bookings!$B$2:$B$140,A8,Bookings!$F$2:$F$140,"Approved")) -> 0 | G8: =IF(A8="","",E8-F8) -> 6 | H8: =IF(OR(A8="",E8=0),"",F8/E8) -> 0
A9: =IF(A8<EOMONTH(DATE(Calendar_View!$E$4,Calendar_View!$M$2,1),0),A8+1,"") -> 46148 | B9: =IF(A9="","",TEXT(A9,"ddd")) -> Wed | C9: =IF(A9="","",IF(WEEKDAY(A9,2)<=5,6,4)) -> 6 | E9: =IF(A9="","",IF(D9<>"",D9,C9)) -> 6 | F9: =IF(A9="","",COUNTIFS(Bookings!$B$2:$B$140,A9,Bookings!$F$2:$F$140,"Approved")) -> 0 | G9: =IF(A9="","",E9-F9) -> 6 | H9: =IF(OR(A9="",E9=0),"",F9/E9) -> 0
A10: =IF(A9<EOMONTH(DATE(Calendar_View!$E$4,Calendar_View!$M$2,1),0),A9+1,"") -> 46149 | B10: =IF(A10="","",TEXT(A10,"ddd")) -> Thu | C10: =IF(A10="","",IF(WEEKDAY(A10,2)<=5,6,4)) -> 6 | E10: =IF(A10="","",IF(D10<>"",D10,C10)) -> 6 | F10: =IF(A10="","",COUNTIFS(Bookings!$B$2:$B$140,A10,Bookings!$F$2:$F$140,"Approved")) -> 0 | G10: =IF(A10="","",E10-F10) -> 6 | H10: =IF(OR(A10="",E10=0),"",F10/E10) -> 0
A11: =IF(A10<EOMONTH(DATE(Calendar_View!$E$4,Calendar_View!$M$2,1),0),A10+1,"") -> 46150 | B11: =IF(A11="","",TEXT(A11,"ddd")) -> Fri | C11: =IF(A11="","",IF(WEEKDAY(A11,2)<=5,6,4)) -> 6 | D11: 8 | E11: =IF(A11="","",IF(D11<>"",D11,C11)) -> 8 | F11: =IF(A11="","",COUNTIFS(Bookings!$B$2:$B$140,A11,Bookings!$F$2:$F$140,"Approved")) -> 0 | G11: =IF(A11="","",E11-F11) -> 8 | H11: =IF(OR(A11="",E11=0),"",F11/E11) -> 0
A12: =IF(A11<EOMONTH(DATE(Calendar_View!$E$4,Calendar_View!$M$2,1),0),A11+1,"") -> 46151 | B12: =IF(A12="","",TEXT(A12,"ddd")) -> Sat | C12: =IF(A12="","",IF(WEEKDAY(A12,2)<=5,6,4)) -> 4 | E12: =IF(A12="","",IF(D12<>"",D12,C12)) -> 4 | F12: =IF(A12="","",COUNTIFS(Bookings!$B$2:$B$140,A12,Bookings!$F$2:$F$140,"Approved")) -> 0 | G12: =IF(A12="","",E12-F12) -> 4 | H12: =IF(OR(A12="",E12=0),"",F12/E12) -> 0
A13: =IF(A12<EOMONTH(DATE(Calendar_View!$E$4,Calendar_View!$M$2,1),0),A12+1,"") -> 46152 | B13: =IF(A13="","",TEXT(A13,"ddd")) -> Sun | C13: =IF(A13="","",IF(WEEKDAY(A13,2)<=5,6,4)) -> 4 | E13: =IF(A13="","",IF(D13<>"",D13,C13)) -> 4 | F13: =IF(A13="","",COUNTIFS(Bookings!$B$2:$B$140,A13,Bookings!$F$2:$F$140,"Approved")) -> 0 | G13: =IF(A13="","",E13-F13) -> 4 | H13: =IF(OR(A13="",E13=0),"",F13/E13) -> 0
A14: =IF(A13<EOMONTH(DATE(Calendar_View!$E$4,Calendar_View!$M$2,1),0),A13+1,"") -> 46153 | B14: =IF(A14="","",TEXT(A14,"ddd")) -> Mon | C14: =IF(A14="","",IF(WEEKDAY(A14,2)<=5,6,4)) -> 6 | E14: =IF(A14="","",IF(D14<>"",D14,C14)) -> 6 | F14: =IF(A14="","",COUNTIFS(Bookings!$B$2:$B$140,A14,Bookings!$F$2:$F$140,"Approved")) -> 0 | G14: =IF(A14="","",E14-F14) -> 6 | H14: =IF(OR(A14="",E14=0),"",F14/E14) -> 0
A15: =IF(A14<EOMONTH(DATE(Calendar_View!$E$4,Calendar_View!$M$2,1),0),A14+1,"") -> 46154 | B15: =IF(A15="","",TEXT(A15,"ddd")) -> Tue | C15: =IF(A15="","",IF(WEEKDAY(A15,2)<=5,6,4)) -> 6 | D15: 3 | E15: =IF(A15="","",IF(D15<>"",D15,C15)) -> 3 | F15: =IF(A15="","",COUNTIFS(Bookings!$B$2:$B$140,A15,Bookings!$F$2:$F$140,"Approved")) -> 0 | G15: =IF(A15="","",E15-F15) -> 3 | H15: =IF(OR(A15="",E15=0),"",F15/E15) -> 0
A16: =IF(A15<EOMONTH(DATE(Calendar_View!$E$4,Calendar_View!$M$2,1),0),A15+1,"") -> 46155 | B16: =IF(A16="","",TEXT(A16,"ddd")) -> Wed | C16: =IF(A16="","",IF(WEEKDAY(A16,2)<=5,6,4)) -> 6 | E16: =IF(A16="","",IF(D16<>"",D16,C16)) -> 6 | F16: =IF(A16="","",COUNTIFS(Bookings!$B$2:$B$140,A16,Bookings!$F$2:$F$140,"Approved")) -> 0 | G16: =IF(A16="","",E16-F16) -> 6 | H16: =IF(OR(A16="",E16=0),"",F16/E16) -> 0
A17: =IF(A16<EOMONTH(DATE(Calendar_View!$E$4,Calendar_View!$M$2,1),0),A16+1,"") -> 46156 | B17: =IF(A17="","",TEXT(A17,"ddd")) -> Thu | C17: =IF(A17="","",IF(WEEKDAY(A17,2)<=5,6,4)) -> 6 | E17: =IF(A17="","",IF(D17<>"",D17,C17)) -> 6 | F17: =IF(A17="","",COUNTIFS(Bookings!$B$2:$B$140,A17,Bookings!$F$2:$F$140,"Approved")) -> 0 | G17: =IF(A17="","",E17-F17) -> 6 | H17: =IF(OR(A17="",E17=0),"",F17/E17) -> 0
A18: =IF(A17<EOMONTH(DATE(Calendar_View!$E$4,Calendar_View!$M$2,1),0),A17+1,"") -> 46157 | B18: =IF(A18="","",TEXT(A18,"ddd")) -> Fri | C18: =IF(A18="","",IF(WEEKDAY(A18,2)<=5,6,4)) -> 6 | D18: 5 | E18: =IF(A18="","",IF(D18<>"",D18,C18)) -> 5 | F18: =IF(A18="","",COUNTIFS(Bookings!$B$2:$B$140,A18,Bookings!$F$2:$F$140,"Approved")) -> 0 | G18: =IF(A18="","",E18-F18) -> 5 | H18: =IF(OR(A18="",E18=0),"",F18/E18) -> 0
A19: =IF(A18<EOMONTH(DATE(Calendar_View!$E$4,Calendar_View!$M$2,1),0),A18+1,"") -> 46158 | B19: =IF(A19="","",TEXT(A19,"ddd")) -> Sat | C19: =IF(A19="","",IF(WEEKDAY(A19,2)<=5,6,4)) -> 4 | E19: =IF(A19="","",IF(D19<>"",D19,C19)) -> 4 | F19: =IF(A19="","",COUNTIFS(Bookings!$B$2:$B$140,A19,Bookings!$F$2:$F$140,"Approved")) -> 0 | G19: =IF(A19="","",E19-F19) -> 4 | H19: =IF(OR(A19="",E19=0),"",F19/E19) -> 0
A20: =IF(A19<EOMONTH(DATE(Calendar_View!$E$4,Calendar_View!$M$2,1),0),A19+1,"") -> 46159 | B20: =IF(A20="","",TEXT(A20,"ddd")) -> Sun | C20: =IF(A20="","",IF(WEEKDAY(A20,2)<=5,6,4)) -> 4 | E20: =IF(A20="","",IF(D20<>"",D20,C20)) -> 4 | F20: =IF(A20="","",COUNTIFS(Bookings!$B$2:$B$140,A20,Bookings!$F$2:$F$140,"Approved")) -> 0 | G20: =IF(A20="","",E20-F20) -> 4 | H20: =IF(OR(A20="",E20=0),"",F20/E20) -> 0
A21: =IF(A20<EOMONTH(DATE(Calendar_View!$E$4,Calendar_View!$M$2,1),0),A20+1,"") -> 46160 | B21: =IF(A21="","",TEXT(A21,"ddd")) -> Mon | C21: =IF(A21="","",IF(WEEKDAY(A21,2)<=5,6,4)) -> 6 | E21: =IF(A21="","",IF(D21<>"",D21,C21)) -> 6 | F21: =IF(A21="","",COUNTIFS(Bookings!$B$2:$B$140,A21,Bookings!$F$2:$F$140,"Approved")) -> 0 | G21: =IF(A21="","",E21-F21) -> 6 | H21: =IF(OR(A21="",E21=0),"",F21/E21) -> 0
A22: =IF(A21<EOMONTH(DATE(Calendar_View!$E$4,Calendar_View!$M$2,1),0),A21+1,"") -> 46161 | B22: =IF(A22="","",TEXT(A22,"ddd")) -> Tue | C22: =IF(A22="","",IF(WEEKDAY(A22,2)<=5,6,4)) -> 6 | E22: =IF(A22="","",IF(D22<>"",D22,C22)) -> 6 | F22: =IF(A22="","",COUNTIFS(Bookings!$B$2:$B$140,A22,Bookings!$F$2:$F$140,"Approved")) -> 0 | G22: =IF(A22="","",E22-F22) -> 6 | H22: =IF(OR(A22="",E22=0),"",F22/E22) -> 0
A23: =IF(A22<EOMONTH(DATE(Calendar_View!$E$4,Calendar_View!$M$2,1),0),A22+1,"") -> 46162 | B23: =IF(A23="","",TEXT(A23,"ddd")) -> Wed | C23: =IF(A23="","",IF(WEEKDAY(A23,2)<=5,6,4)) -> 6 | E23: =IF(A23="","",IF(D23<>"",D23,C23)) -> 6 | F23: =IF(A23="","",COUNTIFS(Bookings!$B$2:$B$140,A23,Bookings!$F$2:$F$140,"Approved")) -> 0 | G23: =IF(A23="","",E23-F23) -> 6 | H23: =IF(OR(A23="",E23=0),"",F23/E23) -> 0
A24: =IF(A23<EOMONTH(DATE(Calendar_View!$E$4,Calendar_View!$M$2,1),0),A23+1,"") -> 46163 | B24: =IF(A24="","",TEXT(A24,"ddd")) -> Thu | C24: =IF(A24="","",IF(WEEKDAY(A24,2)<=5,6,4)) -> 6 | D24: 8 | E24: =IF(A24="","",IF(D24<>"",D24,C24)) -> 8 | F24: =IF(A24="","",COUNTIFS(Bookings!$B$2:$B$140,A24,Bookings!$F$2:$F$140,"Approved")) -> 0 | G24: =IF(A24="","",E24-F24) -> 8 | H24: =IF(OR(A24="",E24=0),"",F24/E24) -> 0
A25: =IF(A24<EOMONTH(DATE(Calendar_View!$E$4,Calendar_View!$M$2,1),0),A24+1,"") -> 46164 | B25: =IF(A25="","",TEXT(A25,"ddd")) -> Fri | C25: =IF(A25="","",IF(WEEKDAY(A25,2)<=5,6,4)) -> 6 | E25: =IF(A25="","",IF(D25<>"",D25,C25)) -> 6 | F25: =IF(A25="","",COUNTIFS(Bookings!$B$2:$B$140,A25,Bookings!$F$2:$F$140,"Approved")) -> 0 | G25: =IF(A25="","",E25-F25) -> 6 | H25: =IF(OR(A25="",E25=0),"",F25/E25) -> 0
A26: =IF(A25<EOMONTH(DATE(Calendar_View!$E$4,Calendar_View!$M$2,1),0),A25+1,"") -> 46165 | B26: =IF(A26="","",TEXT(A26,"ddd")) -> Sat | C26: =IF(A26="","",IF(WEEKDAY(A26,2)<=5,6,4)) -> 4 | E26: =IF(A26="","",IF(D26<>"",D26,C26)) -> 4 | F26: =IF(A26="","",COUNTIFS(Bookings!$B$2:$B$140,A26,Bookings!$F$2:$F$140,"Approved")) -> 0 | G26: =IF(A26="","",E26-F26) -> 4 | H26: =IF(OR(A26="",E26=0),"",F26/E26) -> 0
A27: =IF(A26<EOMONTH(DATE(Calendar_View!$E$4,Calendar_View!$M$2,1),0),A26+1,"") -> 46166 | B27: =IF(A27="","",TEXT(A27,"ddd")) -> Sun | C27: =IF(A27="","",IF(WEEKDAY(A27,2)<=5,6,4)) -> 4 | E27: =IF(A27="","",IF(D27<>"",D27,C27)) -> 4 | F27: =IF(A27="","",COUNTIFS(Bookings!$B$2:$B$140,A27,Bookings!$F$2:$F$140,"Approved")) -> 0 | G27: =IF(A27="","",E27-F27) -> 4 | H27: =IF(OR(A27="",E27=0),"",F27/E27) -> 0
A28: =IF(A27<EOMONTH(DATE(Calendar_View!$E$4,Calendar_View!$M$2,1),0),A27+1,"") -> 46167 | B28: =IF(A28="","",TEXT(A28,"ddd")) -> Mon | C28: =IF(A28="","",IF(WEEKDAY(A28,2)<=5,6,4)) -> 6 | E28: =IF(A28="","",IF(D28<>"",D28,C28)) -> 6 | F28: =IF(A28="","",COUNTIFS(Bookings!$B$2:$B$140,A28,Bookings!$F$2:$F$140,"Approved")) -> 0 | G28: =IF(A28="","",E28-F28) -> 6 | H28: =IF(OR(A28="",E28=0),"",F28/E28) -> 0
A29: =IF(A28<EOMONTH(DATE(Calendar_View!$E$4,Calendar_View!$M$2,1),0),A28+1,"") -> 46168 | B29: =IF(A29="","",TEXT(A29,"ddd")) -> Tue | C29: =IF(A29="","",IF(WEEKDAY(A29,2)<=5,6,4)) -> 6 | E29: =IF(A29="","",IF(D29<>"",D29,C29)) -> 6 | F29: =IF(A29="","",COUNTIFS(Bookings!$B$2:$B$140,A29,Bookings!$F$2:$F$140,"Approved")) -> 0 | G29: =IF(A29="","",E29-F29) -> 6 | H29: =IF(OR(A29="",E29=0),"",F29/E29) -> 0
A30: =IF(A29<EOMONTH(DATE(Calendar_View!$E$4,Calendar_View!$M$2,1),0),A29+1,"") -> 46169 | B30: =IF(A30="","",TEXT(A30,"ddd")) -> Wed | C30: =IF(A30="","",IF(WEEKDAY(A30,2)<=5,6,4)) -> 6 | E30: =IF(A30="","",IF(D30<>"",D30,C30)) -> 6 | F30: =IF(A30="","",COUNTIFS(Bookings!$B$2:$B$140,A30,Bookings!$F$2:$F$140,"Approved")) -> 0 | G30: =IF(A30="","",E30-F30) -> 6 | H30: =IF(OR(A30="",E30=0),"",F30/E30) -> 0
A31: =IF(A30<EOMONTH(DATE(Calendar_View!$E$4,Calendar_View!$M$2,1),0),A30+1,"") -> 46170 | B31: =IF(A31="","",TEXT(A31,"ddd")) -> Thu | C31: =IF(A31="","",IF(WEEKDAY(A31,2)<=5,6,4)) -> 6 | D31: 5 | E31: =IF(A31="","",IF(D31<>"",D31,C31)) -> 5 | F31: =IF(A31="","",COUNTIFS(Bookings!$B$2:$B$140,A31,Bookings!$F$2:$F$140,"Approved")) -> 0 | G31: =IF(A31="","",E31-F31) -> 5 | H31: =IF(OR(A31="",E31=0),"",F31/E31) -> 0
A32: =IF(A31<EOMONTH(DATE(Calendar_View!$E$4,Calendar_View!$M$2,1),0),A31+1,"") -> 46171 | B32: =IF(A32="","",TEXT(A32,"ddd")) -> Fri | C32: =IF(A32="","",IF(WEEKDAY(A32,2)<=5,6,4)) -> 6 | E32: =IF(A32="","",IF(D32<>"",D32,C32)) -> 6 | F32: =IF(A32="","",COUNTIFS(Bookings!$B$2:$B$140,A32,Bookings!$F$2:$F$140,"Approved")) -> 0 | G32: =IF(A32="","",E32-F32) -> 6 | H32: =IF(OR(A32="",E32=0),"",F32/E32) -> 0
A33: =IF(A32<EOMONTH(DATE(Calendar_View!$E$4,Calendar_View!$M$2,1),0),A32+1,"") -> 46172 | B33: =IF(A33="","",TEXT(A33,"ddd")) -> Sat | C33: =IF(A33="","",IF(WEEKDAY(A33,2)<=5,6,4)) -> 4 | E33: =IF(A33="","",IF(D33<>"",D33,C33)) -> 4 | F33: =IF(A33="","",COUNTIFS(Bookings!$B$2:$B$140,A33,Bookings!$F$2:$F$140,"Approved")) -> 0 | G33: =IF(A33="","",E33-F33) -> 4 | H33: =IF(OR(A33="",E33=0),"",F33/E33) -> 0
A34: =IF(A33<EOMONTH(DATE(Calendar_View!$E$4,Calendar_View!$M$2,1),0),A33+1,"") -> 46173 | B34: =IF(A34="","",TEXT(A34,"ddd")) -> Sun | C34: =IF(A34="","",IF(WEEKDAY(A34,2)<=5,6,4)) -> 4 | E34: =IF(A34="","",IF(D34<>"",D34,C34)) -> 4 | F34: =IF(A34="","",COUNTIFS(Bookings!$B$2:$B$140,A34,Bookings!$F$2:$F$140,"Approved")) -> 0 | G34: =IF(A34="","",E34-F34) -> 4 | H34: =IF(OR(A34="",E34=0),"",F34/E34) -> 0

Sheet Bookings
A1: Request ID | B1: Leave Date | C1: Officer | D1: Unit | E1: Category | F1: Status | G1: Notes
A2: REQ-1001 | B2: 46113 | C2: Officer 36 | D2: Ops B | E2: OL | F2: Approved
A3: REQ-1002 | B3: 46113 | C3: Officer 27 | D3: Ops B | E3: Duty Swap | F3: Approved
A4: REQ-1003 | B4: 46113 | C4: Officer 08 | D4: Support | E4: OL | F4: Approved
A5: REQ-1004 | B5: 46113 | C5: Officer 36 | D5: Field | E5: OL | F5: Approved
A6: REQ-1005 | B6: 46114 | C6: Officer 38 | D6: Support | E6: OL | F6: Approved
A7: REQ-1006 | B7: 46114 | C7: Officer 24 | D7: Ops A | E7: Duty Swap | F7: Approved
A8: REQ-1007 | B8: 46114 | C8: Officer 05 | D8: Support | E8: OL | F8: Approved
A9: REQ-1008 | B9: 46114 | C9: Officer 35 | D9: HQ | E9: OL | F9: Cancelled | G9: sample
A10: REQ-1009 | B10: 46115 | C10: Officer 30 | D10: Support | E10: Training | F10: Approved
A11: REQ-1010 | B11: 46115 | C11: Officer 24 | D11: Ops C | E11: OL | F11: Approved
A12: REQ-1011 | B12: 46115 | C12: Officer 12 | D12: Field | E12: OL | F12: Approved
A13: REQ-1012 | B13: 46115 | C13: Officer 06 | D13: Support | E13: OL | F13: Approved
A14: REQ-1013 | B14: 46115 | C14: Officer 34 | D14: HQ | E14: OL | F14: Approved
A15: REQ-1014 | B15: 46115 | C15: Officer 29 | D15: Ops C | E15: Duty Swap | F15: Approved
A16: REQ-1015 | B16: 46116 | C16: Officer 08 | D16: Support | E16: Training | F16: Approved
A17: REQ-1016 | B17: 46116 | C17: Officer 10 | D17: HQ | E17: Training | F17: Cancelled | G17: sample
A18: REQ-1017 | B18: 46117 | C18: Officer 03 | D18: Field | E18: OL | F18: Approved
A19: REQ-1018 | B19: 46117 | C19: Officer 36 | D19: Support | E19: OL | F19: Approved
A20: REQ-1019 | B20: 46117 | C20: Officer 22 | D20: Field | E20: OL | F20: Approved
A21: REQ-1020 | B21: 46117 | C21: Officer 05 | D21: Ops A | E21: OL | F21: Cancelled | G21: sample
A22: REQ-1021 | B22: 46117 | C22: Officer 05 | D22: Ops A | E22: OL | F22: Cancelled | G22: sample
A23: REQ-1022 | B23: 46118 | C23: Officer 37 | D23: Field | E23: Training | F23: Approved
A24: REQ-1023 | B24: 46118 | C24: Officer 19 | D24: Field | E24: Training | F24: Approved
A25: REQ-1024 | B25: 46118 | C25: Officer 30 | D25: Ops C | E25: OL | F25: Pending | G25: sample
A26: REQ-1025 | B26: 46119 | C26: Officer 40 | D26: Ops A | E26: Training | F26: Approved
A27: REQ-1026 | B27: 46119 | C27: Officer 04 | D27: Ops B | E27: OL | F27: Approved
A28: REQ-1027 | B28: 46119 | C28: Officer 09 | D28: Field | E28: OL | F28: Approved
A29: REQ-1028 | B29: 46119 | C29: Officer 26 | D29: HQ | E29: Training | F29: Approved
A30: REQ-1029 | B30: 46120 | C30: Officer 11 | D30: HQ | E30: Training | F30: Approved
A31: REQ-1030 | B31: 46120 | C31: Officer 36 | D31: Ops C | E31: OL | F31: Approved
A32: REQ-1031 | B32: 46120 | C32: Officer 28 | D32: Support | E32: OL | F32: Approved
A33: REQ-1032 | B33: 46120 | C33: Officer 27 | D33: Ops C | E33: Training | F33: Approved
A34: REQ-1033 | B34: 46120 | C34: Officer 15 | D34: Ops B | E34: OL | F34: Approved
A35: REQ-1034 | B35: 46120 | C35: Officer 12 | D35: Ops B | E35: OL | F35: Approved
A36: REQ-1035 | B36: 46120 | C36: Officer 15 | D36: Ops A | E36: Training | F36: Approved
A37: REQ-1036 | B37: 46120 | C37: Officer 19 | D37: Ops A | E37: OL | F37: Cancelled | G37: sample
A38: REQ-1037 | B38: 46121 | C38: Officer 27 | D38: Support | E38: OL | F38: Approved
A39: REQ-1038 | B39: 46121 | C39: Officer 40 | D39: Support | E39: OL | F39: Approved
A40: REQ-1039 | B40: 46121 | C40: Officer 09 | D40: Field | E40: Duty Swap | F40: Approved
...

Sheet Lists
A1: Month Name | B1: Month No | D1: Status | F1: Unit | H1: Category
A2: January | B2: 1 | D2: Approved | F2: Ops A | H2: OL
A3: February | B3: 2 | D3: Pending | F3: Ops B | H3: Training
A4: March | B4: 3 | D4: Cancelled | F4: Ops C | H4: Duty Swap
A5: April | B5: 4 | F5: HQ | H5: Other
A6: May | B6: 5 | F6: Support
A7: June | B7: 6
A8: July | B8: 7
A9: August | B9: 8
A10: September | B10: 9
A11: October | B11: 10
A12: November | B12: 11
A13: December | B13: 12

Sheet _Helper
A1: =DATE(Calendar_View!$E$4,Calendar_View!$M$2,1)-WEEKDAY(DATE(Calendar_View!$E$4,Calendar_View!$M$2,1),2)+1+0 -> 46139 | B1: =DATE(Calendar_View!$E$4,Calendar_View!$M$2,1)-WEEKDAY(DATE(Calendar_View!$E$4,Calendar_View!$M$2,1),2)+1+1 -> 46140 | C1: =DATE(Calendar_View!$E$4,Calendar_View!$M$2,1)-WEEKDAY(DATE(Calendar_View!$E$4,Calendar_View!$M$2,1),2)+1+2 -> 46141 | D1: =DATE(Calendar_View!$E$4,Calendar_View!$M$2,1)-WEEKDAY(DATE(Calendar_View!$E$4,Calendar_View!$M$2,1),2)+1+3 -> 46142 | E1: =DATE(Calendar_View!$E$4,Calendar_View!$M$2,1)-WEEKDAY(DATE(Calendar_View!$E$4,Calendar_View!$M$2,1),2)+1+4 -> 46143 | F1: =DATE(Calendar_View!$E$4,Calendar_View!$M$2,1)-WEEKDAY(DATE(Calendar_View!$E$4,Calendar_View!$M$2,1),2)+1+5 -> 46144 | G1: =DATE(Calendar_View!$E$4,Calendar_View!$M$2,1)-WEEKDAY(DATE(Calendar_View!$E$4,Calendar_View!$M$2,1),2)+1+6 -> 46145
A2: =DATE(Calendar_View!$E$4,Calendar_View!$M$2,1)-WEEKDAY(DATE(Calendar_View!$E$4,Calendar_View!$M$2,1),2)+1+7 -> 46146 | B2: =DATE(Calendar_View!$E$4,Calendar_View!$M$2,1)-WEEKDAY(DATE(Calendar_View!$E$4,Calendar_View!$M$2,1),2)+1+8 -> 46147 | C2: =DATE(Calendar_View!$E$4,Calendar_View!$M$2,1)-WEEKDAY(DATE(Calendar_View!$E$4,Calendar_View!$M$2,1),2)+1+9 -> 46148 | D2: =DATE(Calendar_View!$E$4,Calendar_View!$M$2,1)-WEEKDAY(DATE(Calendar_View!$E$4,Calendar_View!$M$2,1),2)+1+10 -> 46149 | E2: =DATE(Calendar_View!$E$4,Calendar_View!$M$2,1)-WEEKDAY(DATE(Calendar_View!$E$4,Calendar_View!$M$2,1),2)+1+11 -> 46150 | F2: =DATE(Calendar_View!$E$4,Calendar_View!$M$2,1)-WEEKDAY(DATE(Calendar_View!$E$4,Calendar_View!$M$2,1),2)+1+12 -> 46151 | G2: =DATE(Calendar_View!$E$4,Calendar_View!$M$2,1)-WEEKDAY(DATE(Calendar_View!$E$4,Calendar_View!$M$2,1),2)+1+13 -> 46152
A3: =DATE(Calendar_View!$E$4,Calendar_View!$M$2,1)-WEEKDAY(DATE(Calendar_View!$E$4,Calendar_View!$M$2,1),2)+1+14 -> 46153 | B3: =DATE(Calendar_View!$E$4,Calendar_View!$M$2,1)-WEEKDAY(DATE(Calendar_View!$E$4,Calendar_View!$M$2,1),2)+1+15 -> 46154 | C3: =DATE(Calendar_View!$E$4,Calendar_View!$M$2,1)-WEEKDAY(DATE(Calendar_View!$E$4,Calendar_View!$M$2,1),2)+1+16 -> 46155 | D3: =DATE(Calendar_View!$E$4,Calendar_View!$M$2,1)-WEEKDAY(DATE(Calendar_View!$E$4,Calendar_View!$M$2,1),2)+1+17 -> 46156 | E3: =DATE(Calendar_View!$E$4,Calendar_View!$M$2,1)-WEEKDAY(DATE(Calendar_View!$E$4,Calendar_View!$M$2,1),2)+1+18 -> 46157 | F3: =DATE(Calendar_View!$E$4,Calendar_View!$M$2,1)-WEEKDAY(DATE(Calendar_View!$E$4,Calendar_View!$M$2,1),2)+1+19 -> 46158 | G3: =DATE(Calendar_View!$E$4,Calendar_View!$M$2,1)-WEEKDAY(DATE(Calendar_View!$E$4,Calendar_View!$M$2,1),2)+1+20 -> 46159
A4: =DATE(Calendar_View!$E$4,Calendar_View!$M$2,1)-WEEKDAY(DATE(Calendar_View!$E$4,Calendar_View!$M$2,1),2)+1+21 -> 46160 | B4: =DATE(Calendar_View!$E$4,Calendar_View!$M$2,1)-WEEKDAY(DATE(Calendar_View!$E$4,Calendar_View!$M$2,1),2)+1+22 -> 46161 | C4: =DATE(Calendar_View!$E$4,Calendar_View!$M$2,1)-WEEKDAY(DATE(Calendar_View!$E$4,Calendar_View!$M$2,1),2)+1+23 -> 46162 | D4: =DATE(Calendar_View!$E$4,Calendar_View!$M$2,1)-WEEKDAY(DATE(Calendar_View!$E$4,Calendar_View!$M$2,1),2)+1+24 -> 46163 | E4: =DATE(Calendar_View!$E$4,Calendar_View!$M$2,1)-WEEKDAY(DATE(Calendar_View!$E$4,Calendar_View!$M$2,1),2)+1+25 -> 46164 | F4: =DATE(Calendar_View!$E$4,Calendar_View!$M$2,1)-WEEKDAY(DATE(Calendar_View!$E$4,Calendar_View!$M$2,1),2)+1+26 -> 46165 | G4: =DATE(Calendar_View!$E$4,Calendar_View!$M$2,1)-WEEKDAY(DATE(Calendar_View!$E$4,Calendar_View!$M$2,1),2)+1+27 -> 46166
A5: =DATE(Calendar_View!$E$4,Calendar_View!$M$2,1)-WEEKDAY(DATE(Calendar_View!$E$4,Calendar_View!$M$2,1),2)+1+28 -> 46167 | B5: =DATE(Calendar_View!$E$4,Calendar_View!$M$2,1)-WEEKDAY(DATE(Calendar_View!$E$4,Calendar_View!$M$2,1),2)+1+29 -> 46168 | C5: =DATE(Calendar_View!$E$4,Calendar_View!$M$2,1)-WEEKDAY(DATE(Calendar_View!$E$4,Calendar_View!$M$2,1),2)+1+30 -> 46169 | D5: =DATE(Calendar_View!$E$4,Calendar_View!$M$2,1)-WEEKDAY(DATE(Calendar_View!$E$4,Calendar_View!$M$2,1),2)+1+31 -> 46170 | E5: =DATE(Calendar_View!$E$4,Calendar_View!$M$2,1)-WEEKDAY(DATE(Calendar_View!$E$4,Calendar_View!$M$2,1),2)+1+32 -> 46171 | F5: =DATE(Calendar_View!$E$4,Calendar_View!$M$2,1)-WEEKDAY(DATE(Calendar_View!$E$4,Calendar_View!$M$2,1),2)+1+33 -> 46172 | G5: =DATE(Calendar_View!$E$4,Calendar_View!$M$2,1)-WEEKDAY(DATE(Calendar_View!$E$4,Calendar_View!$M$2,1),2)+1+34 -> 46173
A6: =DATE(Calendar_View!$E$4,Calendar_View!$M$2,1)-WEEKDAY(DATE(Calendar_View!$E$4,Calendar_View!$M$2,1),2)+1+35 -> 46174 | B6: =DATE(Calendar_View!$E$4,Calendar_View!$M$2,1)-WEEKDAY(DATE(Calendar_View!$E$4,Calendar_View!$M$2,1),2)+1+36 -> 46175 | C6: =DATE(Calendar_View!$E$4,Calendar_View!$M$2,1)-WEEKDAY(DATE(Calendar_View!$E$4,Calendar_View!$M$2,1),2)+1+37 -> 46176 | D6: =DATE(Calendar_View!$E$4,Calendar_View!$M$2,1)-WEEKDAY(DATE(Calendar_View!$E$4,Calendar_View!$M$2,1),2)+1+38 -> 46177 | E6: =DATE(Calendar_View!$E$4,Calendar_View!$M$2,1)-WEEKDAY(DATE(Calendar_View!$E$4,Calendar_View!$M$2,1),2)+1+39 -> 46178 | F6: =DATE(Calendar_View!$E$4,Calendar_View!$M$2,1)-WEEKDAY(DATE(Calendar_View!$E$4,Calendar_View!$M$2,1),2)+1+40 -> 46179 | G6: =DATE(Calendar_View!$E$4,Calendar_View!$M$2,1)-WEEKDAY(DATE(Calendar_View!$E$4,Calendar_View!$M$2,1),2)+1+41 -> 46180
A9: =IFERROR(INDEX(Daily_Capacity!$F$4:$F$34,MATCH(A1,Daily_Capacity!$A$4:$A$34,0)),"") | B9: =IFERROR(INDEX(Daily_Capacity!$F$4:$F$34,MATCH(B1,Daily_Capacity!$A$4:$A$34,0)),"") | C9: =IFERROR(INDEX(Daily_Capacity!$F$4:$F$34,MATCH(C1,Daily_Capacity!$A$4:$A$34,0)),"") | D9: =IFERROR(INDEX(Daily_Capacity!$F$4:$F$34,MATCH(D1,Daily_Capacity!$A$4:$A$34,0)),"") | E9: =IFERROR(INDEX(Daily_Capacity!$F$4:$F$34,MATCH(E1,Daily_Capacity!$A$4:$A$34,0)),"") -> 0 | F9: =IFERROR(INDEX(Daily_Capacity!$F$4:$F$34,MATCH(F1,Daily_Capacity!$A$4:$A$34,0)),"") -> 0 | G9: =IFERROR(INDEX(Daily_Capacity!$F$4:$F$34,MATCH(G1,Daily_Capacity!$A$4:$A$34,0)),"") -> 0
A10: =IFERROR(INDEX(Daily_Capacity!$F$4:$F$34,MATCH(A2,Daily_Capacity!$A$4:$A$34,0)),"") -> 0 | B10: =IFERROR(INDEX(Daily_Capacity!$F$4:$F$34,MATCH(B2,Daily_Capacity!$A$4:$A$34,0)),"") -> 0 | C10: =IFERROR(INDEX(Daily_Capacity!$F$4:$F$34,MATCH(C2,Daily_Capacity!$A$4:$A$34,0)),"") -> 0 | D10: =IFERROR(INDEX(Daily_Capacity!$F$4:$F$34,MATCH(D2,Daily_Capacity!$A$4:$A$34,0)),"") -> 0 | E10: =IFERROR(INDEX(Daily_Capacity!$F$4:$F$34,MATCH(E2,Daily_Capacity!$A$4:$A$34,0)),"") -> 0 | F10: =IFERROR(INDEX(Daily_Capacity!$F$4:$F$34,MATCH(F2,Daily_Capacity!$A$4:$A$34,0)),"") -> 0 | G10: =IFERROR(INDEX(Daily_Capacity!$F$4:$F$34,MATCH(G2,Daily_Capacity!$A$4:$A$34,0)),"") -> 0
A11: =IFERROR(INDEX(Daily_Capacity!$F$4:$F$34,MATCH(A3,Daily_Capacity!$A$4:$A$34,0)),"") -> 0 | B11: =IFERROR(INDEX(Daily_Capacity!$F$4:$F$34,MATCH(B3,Daily_Capacity!$A$4:$A$34,0)),"") -> 0 | C11: =IFERROR(INDEX(Daily_Capacity!$F$4:$F$34,MATCH(C3,Daily_Capacity!$A$4:$A$34,0)),"") -> 0 | D11: =IFERROR(INDEX(Daily_Capacity!$F$4:$F$34,MATCH(D3,Daily_Capacity!$A$4:$A$34,0)),"") -> 0 | E11: =IFERROR(INDEX(Daily_Capacity!$F$4:$F$34,MATCH(E3,Daily_Capacity!$A$4:$A$34,0)),"") -> 0 | F11: =IFERROR(INDEX(Daily_Capacity!$F$4:$F$34,MATCH(F3,Daily_Capacity!$A$4:$A$34,0)),"") -> 0 | G11: =IFERROR(INDEX(Daily_Capacity!$F$4:$F$34,MATCH(G3,Daily_Capacity!$A$4:$A$34,0)),"") -> 0
A12: =IFERROR(INDEX(Daily_Capacity!$F$4:$F$34,MATCH(A4,Daily_Capacity!$A$4:$A$34,0)),"") -> 0 | B12: =IFERROR(INDEX(Daily_Capacity!$F$4:$F$34,MATCH(B4,Daily_Capacity!$A$4:$A$34,0)),"") -> 0 | C12: =IFERROR(INDEX(Daily_Capacity!$F$4:$F$34,MATCH(C4,Daily_Capacity!$A$4:$A$34,0)),"") -> 0 | D12: =IFERROR(INDEX(Daily_Capacity!$F$4:$F$34,MATCH(D4,Daily_Capacity!$A$4:$A$34,0)),"") -> 0 | E12: =IFERROR(INDEX(Daily_Capacity!$F$4:$F$34,MATCH(E4,Daily_Capacity!$A$4:$A$34,0)),"") -> 0 | F12: =IFERROR(INDEX(Daily_Capacity!$F$4:$F$34,MATCH(F4,Daily_Capacity!$A$4:$A$34,0)),"") -> 0 | G12: =IFERROR(INDEX(Daily_Capacity!$F$4:$F$34,MATCH(G4,Daily_Capacity!$A$4:$A$34,0)),"") -> 0
A13: =IFERROR(INDEX(Daily_Capacity!$F$4:$F$34,MATCH(A5,Daily_Capacity!$A$4:$A$34,0)),"") -> 0 | B13: =IFERROR(INDEX(Daily_Capacity!$F$4:$F$34,MATCH(B5,Daily_Capacity!$A$4:$A$34,0)),"") -> 0 | C13: =IFERROR(INDEX(Daily_Capacity!$F$4:$F$34,MATCH(C5,Daily_Capacity!$A$4:$A$34,0)),"") -> 0 | D13: =IFERROR(INDEX(Daily_Capacity!$F$4:$F$34,MATCH(D5,Daily_Capacity!$A$4:$A$34,0)),"") -> 0 | E13: =IFERROR(INDEX(Daily_Capacity!$F$4:$F$34,MATCH(E5,Daily_Capacity!$A$4:$A$34,0)),"") -> 0 | F13: =IFERROR(INDEX(Daily_Capacity!$F$4:$F$34,MATCH(F5,Daily_Capacity!$A$4:$A$34,0)),"") -> 0 | G13: =IFERROR(INDEX(Daily_Capacity!$F$4:$F$34,MATCH(G5,Daily_Capacity!$A$4:$A$34,0)),"") -> 0
A14: =IFERROR(INDEX(Daily_Capacity!$F$4:$F$34,MATCH(A6,Daily_Capacity!$A$4:$A$34,0)),"") | B14: =IFERROR(INDEX(Daily_Capacity!$F$4:$F$34,MATCH(B6,Daily_Capacity!$A$4:$A$34,0)),"") | C14: =IFERROR(INDEX(Daily_Capacity!$F$4:$F$34,MATCH(C6,Daily_Capacity!$A$4:$A$34,0)),"") | D14: =IFERROR(INDEX(Daily_Capacity!$F$4:$F$34,MATCH(D6,Daily_Capacity!$A$4:$A$34,0)),"") | E14: =IFERROR(INDEX(Daily_Capacity!$F$4:$F$34,MATCH(E6,Daily_Capacity!$A$4:$A$34,0)),"") | F14: =IFERROR(INDEX(Daily_Capacity!$F$4:$F$34,MATCH(F6,Daily_Capacity!$A$4:$A$34,0)),"") | G14: =IFERROR(INDEX(Daily_Capacity!$F$4:$F$34,MATCH(G6,Daily_Capacity!$A$4:$A$34,0)),"")
A17: =IFERROR(INDEX(Daily_Capacity!$E$4:$E$34,MATCH(A1,Daily_Capacity!$A$4:$A$34,0)),"") | B17: =IFERROR(INDEX(Daily_Capacity!$E$4:$E$34,MATCH(B1,Daily_Capacity!$A$4:$A$34,0)),"") | C17: =IFERROR(INDEX(Daily_Capacity!$E$4:$E$34,MATCH(C1,Daily_Capacity!$A$4:$A$34,0)),"") | D17: =IFERROR(INDEX(Daily_Capacity!$E$4:$E$34,MATCH(D1,Daily_Capacity!$A$4:$A$34,0)),"") | E17: =IFERROR(INDEX(Daily_Capacity!$E$4:$E$34,MATCH(E1,Daily_Capacity!$A$4:$A$34,0)),"") -> 6 | F17: =IFERROR(INDEX(Daily_Capacity!$E$4:$E$34,MATCH(F1,Daily_Capacity!$A$4:$A$34,0)),"") -> 4 | G17: =IFERROR(INDEX(Daily_Capacity!$E$4:$E$34,MATCH(G1,Daily_Capacity!$A$4:$A$34,0)),"") -> 4
A18: =IFERROR(INDEX(Daily_Capacity!$E$4:$E$34,MATCH(A2,Daily_Capacity!$A$4:$A$34,0)),"") -> 6 | B18: =IFERROR(INDEX(Daily_Capacity!$E$4:$E$34,MATCH(B2,Daily_Capacity!$A$4:$A$34,0)),"") -> 6 | C18: =IFERROR(INDEX(Daily_Capacity!$E$4:$E$34,MATCH(C2,Daily_Capacity!$A$4:$A$34,0)),"") -> 6 | D18: =IFERROR(INDEX(Daily_Capacity!$E$4:$E$34,MATCH(D2,Daily_Capacity!$A$4:$A$34,0)),"") -> 6 | E18: =IFERROR(INDEX(Daily_Capacity!$E$4:$E$34,MATCH(E2,Daily_Capacity!$A$4:$A$34,0)),"") -> 8 | F18: =IFERROR(INDEX(Daily_Capacity!$E$4:$E$34,MATCH(F2,Daily_Capacity!$A$4:$A$34,0)),"") -> 4 | G18: =IFERROR(INDEX(Daily_Capacity!$E$4:$E$34,MATCH(G2,Daily_Capacity!$A$4:$A$34,0)),"") -> 4
A19: =IFERROR(INDEX(Daily_Capacity!$E$4:$E$34,MATCH(A3,Daily_Capacity!$A$4:$A$34,0)),"") -> 6 | B19: =IFERROR(INDEX(Daily_Capacity!$E$4:$E$34,MATCH(B3,Daily_Capacity!$A$4:$A$34,0)),"") -> 3 | C19: =IFERROR(INDEX(Daily_Capacity!$E$4:$E$34,MATCH(C3,Daily_Capacity!$A$4:$A$34,0)),"") -> 6 | D19: =IFERROR(INDEX(Daily_Capacity!$E$4:$E$34,MATCH(D3,Daily_Capacity!$A$4:$A$34,0)),"") -> 6 | E19: =IFERROR(INDEX(Daily_Capacity!$E$4:$E$34,MATCH(E3,Daily_Capacity!$A$4:$A$34,0)),"") -> 5 | F19: =IFERROR(INDEX(Daily_Capacity!$E$4:$E$34,MATCH(F3,Daily_Capacity!$A$4:$A$34,0)),"") -> 4 | G19: =IFERROR(INDEX(Daily_Capacity!$E$4:$E$34,MATCH(G3,Daily_Capacity!$A$4:$A$34,0)),"") -> 4
A20: =IFERROR(INDEX(Daily_Capacity!$E$4:$E$34,MATCH(A4,Daily_Capacity!$A$4:$A$34,0)),"") -> 6 | B20: =IFERROR(INDEX(Daily_Capacity!$E$4:$E$34,MATCH(B4,Daily_Capacity!$A$4:$A$34,0)),"") -> 6 | C20: =IFERROR(INDEX(Daily_Capacity!$E$4:$E$34,MATCH(C4,Daily_Capacity!$A$4:$A$34,0)),"") -> 6 | D20: =IFERROR(INDEX(Daily_Capacity!$E$4:$E$34,MATCH(D4,Daily_Capacity!$A$4:$A$34,0)),"") -> 8 | E20: =IFERROR(INDEX(Daily_Capacity!$E$4:$E$34,MATCH(E4,Daily_Capacity!$A$4:$A$34,0)),"") -> 6 | F20: =IFERROR(INDEX(Daily_Capacity!$E$4:$E$34,MATCH(F4,Daily_Capacity!$A$4:$A$34,0)),"") -> 4 | G20: =IFERROR(INDEX(Daily_Capacity!$E$4:$E$34,MATCH(G4,Daily_Capacity!$A$4:$A$34,0)),"") -> 4
A21: =IFERROR(INDEX(Daily_Capacity!$E$4:$E$34,MATCH(A5,Daily_Capacity!$A$4:$A$34,0)),"") -> 6 | B21: =IFERROR(INDEX(Daily_Capacity!$E$4:$E$34,MATCH(B5,Daily_Capacity!$A$4:$A$34,0)),"") -> 6 | C21: =IFERROR(INDEX(Daily_Capacity!$E$4:$E$34,MATCH(C5,Daily_Capacity!$A$4:$A$34,0)),"") -> 6 | D21: =IFERROR(INDEX(Daily_Capacity!$E$4:$E$34,MATCH(D5,Daily_Capacity!$A$4:$A$34,0)),"") -> 5 | E21: =IFERROR(INDEX(Daily_Capacity!$E$4:$E$34,MATCH(E5,Daily_Capacity!$A$4:$A$34,0)),"") -> 6 | F21: =IFERROR(INDEX(Daily_Capacity!$E$4:$E$34,MATCH(F5,Daily_Capacity!$A$4:$A$34,0)),"") -> 4 | G21: =IFERROR(INDEX(Daily_Capacity!$E$4:$E$34,MATCH(G5,Daily_Capacity!$A$4:$A$34,0)),"") -> 4
A22: =IFERROR(INDEX(Daily_Capacity!$E$4:$E$34,MATCH(A6,Daily_Capacity!$A$4:$A$34,0)),"") | B22: =IFERROR(INDEX(Daily_Capacity!$E$4:$E$34,MATCH(B6,Daily_Capacity!$A$4:$A$34,0)),"") | C22: =IFERROR(INDEX(Daily_Capacity!$E$4:$E$34,MATCH(C6,Daily_Capacity!$A$4:$A$34,0)),"") | D22: =IFERROR(INDEX(Daily_Capacity!$E$4:$E$34,MATCH(D6,Daily_Capacity!$A$4:$A$34,0)),"") | E22: =IFERROR(INDEX(Daily_Capacity!$E$4:$E$34,MATCH(E6,Daily_Capacity!$A$4:$A$34,0)),"") | F22: =IFERROR(INDEX(Daily_Capacity!$E$4:$E$34,MATCH(F6,Daily_Capacity!$A$4:$A$34,0)),"") | G22: =IFERROR(INDEX(Daily_Capacity!$E$4:$E$34,MATCH(G6,Daily_Capacity!$A$4:$A$34,0)),"")
A25: =IFERROR(INDEX(Daily_Capacity!$G$4:$G$34,MATCH(A1,Daily_Capacity!$A$4:$A$34,0)),"") | B25: =IFERROR(INDEX(Daily_Capacity!$G$4:$G$34,MATCH(B1,Daily_Capacity!$A$4:$A$34,0)),"") | C25: =IFERROR(INDEX(Daily_Capacity!$G$4:$G$34,MATCH(C1,Daily_Capacity!$A$4:$A$34,0)),"") | D25: =IFERROR(INDEX(Daily_Capacity!$G$4:$G$34,MATCH(D1,Daily_Capacity!$A$4:$A$34,0)),"") | E25: =IFERROR(INDEX(Daily_Capacity!$G$4:$G$34,MATCH(E1,Daily_Capacity!$A$4:$A$34,0)),"") -> 6 | F25: =IFERROR(INDEX(Daily_Capacity!$G$4:$G$34,MATCH(F1,Daily_Capacity!$A$4:$A$34,0)),"") -> 4 | G25: =IFERROR(INDEX(Daily_Capacity!$G$4:$G$34,MATCH(G1,Daily_Capacity!$A$4:$A$34,0)),"") -> 4
A26: =IFERROR(INDEX(Daily_Capacity!$G$4:$G$34,MATCH(A2,Daily_Capacity!$A$4:$A$34,0)),"") -> 6 | B26: =IFERROR(INDEX(Daily_Capacity!$G$4:$G$34,MATCH(B2,Daily_Capacity!$A$4:$A$34,0)),"") -> 6 | C26: =IFERROR(INDEX(Daily_Capacity!$G$4:$G$34,MATCH(C2,Daily_Capacity!$A$4:$A$34,0)),"") -> 6 | D26: =IFERROR(INDEX(Daily_Capacity!$G$4:$G$34,MATCH(D2,Daily_Capacity!$A$4:$A$34,0)),"") -> 6 | E26: =IFERROR(INDEX(Daily_Capacity!$G$4:$G$34,MATCH(E2,Daily_Capacity!$A$4:$A$34,0)),"") -> 8 | F26: =IFERROR(INDEX(Daily_Capacity!$G$4:$G$34,MATCH(F2,Daily_Capacity!$A$4:$A$34,0)),"") -> 4 | G26: =IFERROR(INDEX(Daily_Capacity!$G$4:$G$34,MATCH(G2,Daily_Capacity!$A$4:$A$34,0)),"") -> 4
A27: =IFERROR(INDEX(Daily_Capacity!$G$4:$G$34,MATCH(A3,Daily_Capacity!$A$4:$A$34,0)),"") -> 6 | B27: =IFERROR(INDEX(Daily_Capacity!$G$4:$G$34,MATCH(B3,Daily_Capacity!$A$4:$A$34,0)),"") -> 3 | C27: =IFERROR(INDEX(Daily_Capacity!$G$4:$G$34,MATCH(C3,Daily_Capacity!$A$4:$A$34,0)),"") -> 6 | D27: =IFERROR(INDEX(Daily_Capacity!$G$4:$G$34,MATCH(D3,Daily_Capacity!$A$4:$A$34,0)),"") -> 6 | E27: =IFERROR(INDEX(Daily_Capacity!$G$4:$G$34,MATCH(E3,Daily_Capacity!$A$4:$A$34,0)),"") -> 5 | F27: =IFERROR(INDEX(Daily_Capacity!$G$4:$G$34,MATCH(F3,Daily_Capacity!$A$4:$A$34,0)),"") -> 4 | G27: =IFERROR(INDEX(Daily_Capacity!$G$4:$G$34,MATCH(G3,Daily_Capacity!$A$4:$A$34,0)),"") -> 4
A28: =IFERROR(INDEX(Daily_Capacity!$G$4:$G$34,MATCH(A4,Daily_Capacity!$A$4:$A$34,0)),"") -> 6 | B28: =IFERROR(INDEX(Daily_Capacity!$G$4:$G$34,MATCH(B4,Daily_Capacity!$A$4:$A$34,0)),"") -> 6 | C28: =IFERROR(INDEX(Daily_Capacity!$G$4:$G$34,MATCH(C4,Daily_Capacity!$A$4:$A$34,0)),"") -> 6 | D28: =IFERROR(INDEX(Daily_Capacity!$G$4:$G$34,MATCH(D4,Daily_Capacity!$A$4:$A$34,0)),"") -> 8 | E28: =IFERROR(INDEX(Daily_Capacity!$G$4:$G$34,MATCH(E4,Daily_Capacity!$A$4:$A$34,0)),"") -> 6 | F28: =IFERROR(INDEX(Daily_Capacity!$G$4:$G$34,MATCH(F4,Daily_Capacity!$A$4:$A$34,0)),"") -> 4 | G28: =IFERROR(INDEX(Daily_Capacity!$G$4:$G$34,MATCH(G4,Daily_Capacity!$A$4:$A$34,0)),"") -> 4
A29: =IFERROR(INDEX(Daily_Capacity!$G$4:$G$34,MATCH(A5,Daily_Capacity!$A$4:$A$34,0)),"") -> 6 | B29: =IFERROR(INDEX(Daily_Capacity!$G$4:$G$34,MATCH(B5,Daily_Capacity!$A$4:$A$34,0)),"") -> 6 | C29: =IFERROR(INDEX(Daily_Capacity!$G$4:$G$34,MATCH(C5,Daily_Capacity!$A$4:$A$34,0)),"") -> 6 | D29: =IFERROR(INDEX(Daily_Capacity!$G$4:$G$34,MATCH(D5,Daily_Capacity!$A$4:$A$34,0)),"") -> 5 | E29: =IFERROR(INDEX(Daily_Capacity!$G$4:$G$34,MATCH(E5,Daily_Capacity!$A$4:$A$34,0)),"") -> 6 | F29: =IFERROR(INDEX(Daily_Capacity!$G$4:$G$34,MATCH(F5,Daily_Capacity!$A$4:$A$34,0)),"") -> 4 | G29: =IFERROR(INDEX(Daily_Capacity!$G$4:$G$34,MATCH(G5,Daily_Capacity!$A$4:$A$34,0)),"") -> 4
A30: =IFERROR(INDEX(Daily_Capacity!$G$4:$G$34,MATCH(A6,Daily_Capacity!$A$4:$A$34,0)),"") | B30: =IFERROR(INDEX(Daily_Capacity!$G$4:$G$34,MATCH(B6,Daily_Capacity!$A$4:$A$34,0)),"") | C30: =IFERROR(INDEX(Daily_Capacity!$G$4:$G$34,MATCH(C6,Daily_Capacity!$A$4:$A$34,0)),"") | D30: =IFERROR(INDEX(Daily_Capacity!$G$4:$G$34,MATCH(D6,Daily_Capacity!$A$4:$A$34,0)),"") | E30: =IFERROR(INDEX(Daily_Capacity!$G$4:$G$34,MATCH(E6,Daily_Capacity!$A$4:$A$34,0)),"") | F30: =IFERROR(INDEX(Daily_Capacity!$G$4:$G$34,MATCH(F6,Daily_Capacity!$A$4:$A$34,0)),"") | G30: =IFERROR(INDEX(Daily_Capacity!$G$4:$G$34,MATCH(G6,Daily_Capacity!$A$4:$A$34,0)),"")
