Workbook

Sheet 2025
A1: Date of Submmision | B1: Scheme | C1: Rank | D1: Name of Officer applying for leave (Full Name) | E1: Country of Travel Country, State | F1: Own Quota/ Borrowed Quota | G1: Date of Departure | H1: Date of Return | I1: Leave Approving Officer in HRP | J1: Unit's Leave Quota | K1: OC Approved? | L1: Unit | M1: Remarks
A2: 45284 | B2: Reg | C2: SI | D2: Zainal Abideen Bin Abdul Wahid | E2: Malaysia, KL | F2: Own Quota | G2: 45647 | H2: 45658 | I2: INSP Tarmizi | J2: {=MAX(IF(YEAR(_xlfn.SEQUENCE(Table1[[#This Row],[Date of Return]] - Table1[[#This Row],[Date of Departure]] + 1, , Table1[[#This Row],[Date of Departure]])) = YEAR(Table1[[#This Row],[Date of Departure]]), COUNTIFS(Table1[Date of Departure], "<=" & _xlfn.SEQUENCE(Table1[[#This Row],[Date of Return]] - Table1[[#This Row],[Date of Departure]] + 1, , Table1[[#This Row],[Date of Departure]]), Table1[Date of Return], ">=" & _xlfn.SEQUENCE(Table1[[#This Row],[Date of Return]] - Table1[[#This Row],[Date of Departure]] + 1, , Table1[[#This Row],[Date of Departure]]), Table1[Date of Departure], ">=" & DATE(YEAR(Table1[[#This Row],[Date of Departure]]),1,1), Table1[Date of Departure], "<=" & DATE(YEAR(Table1[[#This Row],[Date of Departure]]),12,31)), 0))} -> 2 | K2: =IF(Table1[[#This Row],[Unit''s Leave Quota]]<=6, "Approved", "Quota Exceeded") -> Approved
A3: 45347 | B3: Reg | C3: SI | D3: Shahril Bin Mohamed Faru | E3: Austria | F3: Own Quota | G3: 45646 | H3: 45662 | I3: ASP Jonathan Ling | J3: {=MAX(COUNTIFS(Table1[Date of Departure], "<=" & _xlfn.SEQUENCE(Table1[[#This Row],[Date of Return]] - Table1[[#This Row],[Date of Departure]] + 1, , Table1[[#This Row],[Date of Departure]]), Table1[Date of Return], ">=" & _xlfn.SEQUENCE(Table1[[#This Row],[Date of Return]] - Table1[[#This Row],[Date of Departure]] + 1, , Table1[[#This Row],[Date of Departure]])))} -> 5 | K3: =IF(Table1[[#This Row],[Unit''s Leave Quota]]<=6, "Approved", "Quota Exceeded") -> Approved
A4: 45459 | B4: Reg | C4: Sgt(3) | D4: Mohd Khalid Bin Mohd Ariff | E4: London | F4: Own Quota | G4: 45665 | H4: 45680 | I4: ASP Jannah Wong | J4: {=MAX(COUNTIFS(Table1[Date of Departure], "<=" & _xlfn.SEQUENCE(Table1[[#This Row],[Date of Return]] - Table1[[#This Row],[Date of Departure]] + 1, , Table1[[#This Row],[Date of Departure]]), Table1[Date of Return], ">=" & _xlfn.SEQUENCE(Table1[[#This Row],[Date of Return]] - Table1[[#This Row],[Date of Departure]] + 1, , Table1[[#This Row],[Date of Departure]])))} -> 6 | K4: =IF(Table1[[#This Row],[Unit''s Leave Quota]]<=6, "Approved", "Quota Exceeded") -> Approved
A5: 45526 | B5: Reg | C5: Sgt(3) | D5: Tan Yi Xin | E5: Seoul, South Korea/ Tokyo, Japan | F5: Own Quota | G5: 45660 | H5: 45672 | I5: ASP Tarmizi | J5: {=MAX(COUNTIFS(Table1[Date of Departure], "<=" & _xlfn.SEQUENCE(Table1[[#This Row],[Date of Return]] - Table1[[#This Row],[Date of Departure]] + 1, , Table1[[#This Row],[Date of Departure]]), Table1[Date of Return], ">=" & _xlfn.SEQUENCE(Table1[[#This Row],[Date of Return]] - Table1[[#This Row],[Date of Departure]] + 1, , Table1[[#This Row],[Date of Departure]])))} -> 6 | K5: =IF(Table1[[#This Row],[Unit''s Leave Quota]]<=6, "Approved", "Quota Exceeded") -> Approved
A6: 45554 | B6: Reg | C6: ASP(1) | D6: Christopher Tan | E6: China | F6: Own Quota | G6: 45659 | H6: 45666 | I6: DSP Idil | J6: {=MAX(COUNTIFS(Table1[Date of Departure], "<=" & _xlfn.SEQUENCE(Table1[[#This Row],[Date of Return]] - Table1[[#This Row],[Date of Departure]] + 1, , Table1[[#This Row],[Date of Departure]]), Table1[Date of Return], ">=" & _xlfn.SEQUENCE(Table1[[#This Row],[Date of Return]] - Table1[[#This Row],[Date of Departure]] + 1, , Table1[[#This Row],[Date of Departure]])))} -> 6 | K6: =IF(Table1[[#This Row],[Unit''s Leave Quota]]<=6, "Approved", "Quota Exceeded") -> Approved | M6: 2nd (1st quota used); 3rd-8th (3rd quota used); 9th (2nd quota used)
A7: 45554 | B7: Reg | C7: ASP(1) | D7: Christopher Tan | E7: London | F7: Own Quota | G7: 45717 | H7: 45728 | I7: DSP Idil | J7: {=MAX(COUNTIFS(Table1[Date of Departure], "<=" & _xlfn.SEQUENCE(Table1[[#This Row],[Date of Return]] - Table1[[#This Row],[Date of Departure]] + 1, , Table1[[#This Row],[Date of Departure]]), Table1[Date of Return], ">=" & _xlfn.SEQUENCE(Table1[[#This Row],[Date of Return]] - Table1[[#This Row],[Date of Departure]] + 1, , Table1[[#This Row],[Date of Departure]])))} -> 6 | K7: =IF(Table1[[#This Row],[Unit''s Leave Quota]]<=6, "Approved", "Quota Exceeded") -> Approved
A8: 45574 | B8: Reg | C8: ASP(1) | D8: Wong Min, Jannah | E8: Malaysia (Cruise) | F8: Own Quota | G8: 45673 | H8: 45677 | I8: DSP Idil | J8: {=MAX(COUNTIFS(Table1[Date of Departure], "<=" & _xlfn.SEQUENCE(Table1[[#This Row],[Date of Return]] - Table1[[#This Row],[Date of Departure]] + 1, , Table1[[#This Row],[Date of Departure]]), Table1[Date of Return], ">=" & _xlfn.SEQUENCE(Table1[[#This Row],[Date of Return]] - Table1[[#This Row],[Date of Departure]] + 1, , Table1[[#This Row],[Date of Departure]])))} -> 6 | K8: =IF(Table1[[#This Row],[Unit''s Leave Quota]]<=6, "Approved", "Quota Exceeded") -> Approved
A9: 45619 | B9: Reg | C9: ASP(2) | D9: Darrick Chew Wei Le | E9: China, Yunnan | F9: Own Quota | G9: 45660 | H9: 45669 | I9: DSP Idil | J9: {=MAX(COUNTIFS(Table1[Date of Departure], "<=" & _xlfn.SEQUENCE(Table1[[#This Row],[Date of Return]] - Table1[[#This Row],[Date of Departure]] + 1, , Table1[[#This Row],[Date of Departure]]), Table1[Date of Return], ">=" & _xlfn.SEQUENCE(Table1[[#This Row],[Date of Return]] - Table1[[#This Row],[Date of Departure]] + 1, , Table1[[#This Row],[Date of Departure]])))} -> 6 | K9: =IF(Table1[[#This Row],[Unit''s Leave Quota]]<=6, "Approved", "Quota Exceeded") -> Approved
A10: 45619 | B10: Reg | C10: ASP(2) | D10: Darrick Chew Wei Le | E10: Japan, Hokkaido | F10: Own Quota | G10: 45787 | H10: 45795 | I10: DSP Idil | J10: {=MAX(COUNTIFS(Table1[Date of Departure], "<=" & _xlfn.SEQUENCE(Table1[[#This Row],[Date of Return]] - Table1[[#This Row],[Date of Departure]] + 1, , Table1[[#This Row],[Date of Departure]]), Table1[Date of Return], ">=" & _xlfn.SEQUENCE(Table1[[#This Row],[Date of Return]] - Table1[[#This Row],[Date of Departure]] + 1, , Table1[[#This Row],[Date of Departure]])))} -> 6 | K10: =IF(Table1[[#This Row],[Unit''s Leave Quota]]<=6, "Approved", "Quota Exceeded") -> Approved
A11: 45628 | B11: Reg | C11: SSgt | D11: Muhammad Haidar Bin Tayib | E11: Malaysia Kelantan | F11: Own Quota | G11: 45701 | H11: 45704 | I11: ASP Darrick Chew | J11: {=MAX(COUNTIFS(Table1[Date of Departure], "<=" & _xlfn.SEQUENCE(Table1[[#This Row],[Date of Return]] - Table1[[#This Row],[Date of Departure]] + 1, , Table1[[#This Row],[Date of Departure]]), Table1[Date of Return], ">=" & _xlfn.SEQUENCE(Table1[[#This Row],[Date of Return]] - Table1[[#This Row],[Date of Departure]] + 1, , Table1[[#This Row],[Date of Departure]])))} -> 4 | K11: =IF(Table1[[#This Row],[Unit''s Leave Quota]]<=6, "Approved", "Quota Exceeded") -> Approved
A12: 45637 | B12: Reg | C12: Sgt(3) | D12: Lokman Bin Abdul Ghani | E12: Saudi Arabia | F12: Own Quota | G12: 45701 | H12: 45708 | I12: ASP Christopher | J12: {=MAX(COUNTIFS(Table1[Date of Departure], "<=" & _xlfn.SEQUENCE(Table1[[#This Row],[Date of Return]] - Table1[[#This Row],[Date of Departure]] + 1, , Table1[[#This Row],[Date of Departure]]), Table1[Date of Return], ">=" & _xlfn.SEQUENCE(Table1[[#This Row],[Date of Return]] - Table1[[#This Row],[Date of Departure]] + 1, , Table1[[#This Row],[Date of Departure]])))} -> 4 | K12: =IF(Table1[[#This Row],[Unit''s Leave Quota]]<=6, "Approved", "Quota Exceeded") -> Approved
A13: 45639 | B13: Reg | C13: Sgt(2) | D13: Chan Wei Jie | E13: Desaru | F13: Own Quota | G13: 45665 | H13: 45668 | I13: ASP Jannah Wong | J13: {=MAX(COUNTIFS(Table1[Date of Departure], "<=" & _xlfn.SEQUENCE(Table1[[#This Row],[Date of Return]] - Table1[[#This Row],[Date of Departure]] + 1, , Table1[[#This Row],[Date of Departure]]), Table1[Date of Return], ">=" & _xlfn.SEQUENCE(Table1[[#This Row],[Date of Return]] - Table1[[#This Row],[Date of Departure]] + 1, , Table1[[#This Row],[Date of Departure]])))} -> 6 | K13: =IF(Table1[[#This Row],[Unit''s Leave Quota]]<=6, "Approved", "Quota Exceeded") -> Approved | M13: 8th and 9th (5th quota), 10th and 11th (4th quota)
A14: 45643 | B14: Reg | C14: Sgt(2) | D14: Chan Wei Jie | E14: Penang, Malaysia | F14: Own Quota | G14: 45839 | H14: 45842 | I14: ASP Jannah Wong | J14: {=MAX(COUNTIFS(Table1[Date of Departure], "<=" & _xlfn.SEQUENCE(Table1[[#This Row],[Date of Return]] - Table1[[#This Row],[Date of Departure]] + 1, , Table1[[#This Row],[Date of Departure]]), Table1[Date of Return], ">=" & _xlfn.SEQUENCE(Table1[[#This Row],[Date of Return]] - Table1[[#This Row],[Date of Departure]] + 1, , Table1[[#This Row],[Date of Departure]])))} -> 5 | K14: =IF(Table1[[#This Row],[Unit''s Leave Quota]]<=6, "Approved", "Quota Exceeded") -> Approved
A15: 45648 | B15: Reg | C15: SSSgt | D15: Jacqueline Quek Jie Lin | E15: Malaysia, Desaru | F15: Own Quota | G15: 45661 | H15: 45662 | I15: DSP Choo Yi Jie | J15: {=MAX(COUNTIFS(Table1[Date of Departure], "<=" & _xlfn.SEQUENCE(Table1[[#This Row],[Date of Return]] - Table1[[#This Row],[Date of Departure]] + 1, , Table1[[#This Row],[Date of Departure]]), Table1[Date of Return], ">=" & _xlfn.SEQUENCE(Table1[[#This Row],[Date of Return]] - Table1[[#This Row],[Date of Departure]] + 1, , Table1[[#This Row],[Date of Departure]])))} -> 5 | K15: =IF(Table1[[#This Row],[Unit''s Leave Quota]]<=6, "Approved", "Quota Exceeded") -> Approved
A16: 45648 | B16: Reg | C16: Sgt(2) | D16: Philson Ang Hong Giap | E16: South Korea, Seoul | F16: Own Quota | G16: 45694 | H16: 45701 | I16: DSP Choo Yi Jie | J16: {=MAX(COUNTIFS(Table1[Date of Departure], "<=" & _xlfn.SEQUENCE(Table1[[#This Row],[Date of Return]] - Table1[[#This Row],[Date of Departure]] + 1, , Table1[[#This Row],[Date of Departure]]), Table1[Date of Return], ">=" & _xlfn.SEQUENCE(Table1[[#This Row],[Date of Return]] - Table1[[#This Row],[Date of Departure]] + 1, , Table1[[#This Row],[Date of Departure]])))} -> 4 | K16: =IF(Table1[[#This Row],[Unit''s Leave Quota]]<=6, "Approved", "Quota Exceeded") -> Approved | M16: 13 Feb (2nd quota used)
A17: 45648 | B17: Reg | C17: SI | D17: Armizat Bin Saini | E17: Saudi Arabia | F17: Own Quota | G17: 45711 | H17: 45725 | I17: DSP Choo Yi Jie | J17: {=MAX(COUNTIFS(Table1[Date of Departure], "<=" & _xlfn.SEQUENCE(Table1[[#This Row],[Date of Return]] - Table1[[#This Row],[Date of Departure]] + 1, , Table1[[#This Row],[Date of Departure]]), Table1[Date of Return], ">=" & _xlfn.SEQUENCE(Table1[[#This Row],[Date of Return]] - Table1[[#This Row],[Date of Departure]] + 1, , Table1[[#This Row],[Date of Departure]])))} -> 6 | K17: =IF(Table1[[#This Row],[Unit''s Leave Quota]]<=6, "Approved", "Quota Exceeded") -> Approved | M17: 1-9 Mar (1st quota used)
A18: 45648 | B18: Reg | C18: SSgt | D18: Mohammad 'Isa Bin Abdul Ghafar | E18: Indonesia | F18: Own Quota | G18: 45787 | H18: 45793 | I18: DSP Choo Yi Jie | J18: {=MAX(COUNTIFS(Table1[Date of Departure], "<=" & _xlfn.SEQUENCE(Table1[[#This Row],[Date of Return]] - Table1[[#This Row],[Date of Departure]] + 1, , Table1[[#This Row],[Date of Departure]]), Table1[Date of Return], ">=" & _xlfn.SEQUENCE(Table1[[#This Row],[Date of Return]] - Table1[[#This Row],[Date of Departure]] + 1, , Table1[[#This Row],[Date of Departure]])))} -> 6 | K18: =IF(Table1[[#This Row],[Unit''s Leave Quota]]<=6, "Approved", "Quota Exceeded") -> Approved
A19: 45649 | B19: Reg | C19: SI | D19: Muhammad Sazali Bin Samaludin | E19: Malaysia / Thailand | F19: Borrowed Quota | G19: 46006 | H19: 46015 | I19: ASP Tarmizi | J19: {=MAX(COUNTIFS(Table1[Date of Departure], "<=" & _xlfn.SEQUENCE(Table1[[#This Row],[Date of Return]] - Table1[[#This Row],[Date of Departure]] + 1, , Table1[[#This Row],[Date of Departure]]), Table1[Date of Return], ">=" & _xlfn.SEQUENCE(Table1[[#This Row],[Date of Return]] - Table1[[#This Row],[Date of Departure]] + 1, , Table1[[#This Row],[Date of Departure]])))} -> 7 | K19: =IF(Table1[[#This Row],[Unit''s Leave Quota]]<=6, "Approved", "Quota Exceeded") -> Quota Exceeded | M19: As of 17th Dec, Officer quota at Ops [Please view comment]
A20: 45650 | B20: Reg | C20: Sgt(3) | D20: M Faiz Fazely | E20: Malaysia, KL | F20: Own Quota | G20: 45666 | H20: 45670 | I20: ASP Christopher | J20: {=MAX(COUNTIFS(Table1[Date of Departure], "<=" & _xlfn.SEQUENCE(Table1[[#This Row],[Date of Return]] - Table1[[#This Row],[Date of Departure]] + 1, , Table1[[#This Row],[Date of Departure]]), Table1[Date of Return], ">=" & _xlfn.SEQUENCE(Table1[[#This Row],[Date of Return]] - Table1[[#This Row],[Date of Departure]] + 1, , Table1[[#This Row],[Date of Departure]])))} -> 6 | K20: =IF(Table1[[#This Row],[Unit''s Leave Quota]]<=6, "Approved", "Quota Exceeded") -> Approved | M20: 9th (using 6th quota), 10th - 11th (using 5th quota), 12th (using 4th quota), 13th (using 3rd quota)
A21: 45650 | B21: Reg | C21: Sgt(3) | D21: Alvin Wee Han Kuang | E21: Saudi Arabia | F21: Own Quota | G21: 45722 | H21: 45726 | I21: ASP Jannah Wong | J21: {=MAX(COUNTIFS(Table1[Date of Departure], "<=" & _xlfn.SEQUENCE(Table1[[#This Row],[Date of Return]] - Table1[[#This Row],[Date of Departure]] + 1, , Table1[[#This Row],[Date of Departure]]), Table1[Date of Return], ">=" & _xlfn.SEQUENCE(Table1[[#This Row],[Date of Return]] - Table1[[#This Row],[Date of Departure]] + 1, , Table1[[#This Row],[Date of Departure]])))} -> 6 | K21: =IF(Table1[[#This Row],[Unit''s Leave Quota]]<=6, "Approved", "Quota Exceeded") -> Approved
A22: 45652 | B22: Reg | C22: Sgt(3) | D22: Faizal Toh | E22: Thailand | F22: Own Quota | G22: 45706 | H22: 45714 | I22: ASP Jannah Wong | J22: {=MAX(COUNTIFS(Table1[Date of Departure], "<=" & _xlfn.SEQUENCE(Table1[[#This Row],[Date of Return]] - Table1[[#This Row],[Date of Departure]] + 1, , Table1[[#This Row],[Date of Departure]]), Table1[Date of Return], ">=" & _xlfn.SEQUENCE(Table1[[#This Row],[Date of Return]] - Table1[[#This Row],[Date of Departure]] + 1, , Table1[[#This Row],[Date of Departure]])))} -> 6 | K22: =IF(Table1[[#This Row],[Unit''s Leave Quota]]<=6, "Approved", "Quota Exceeded") -> Approved | M22: 18-20, 23-26 (1st quota) / 21-22 (0 quota)
A23: 45655 | B23: Reg | C23: Sgt(3) | D23: Faizal Toh | E23: Malaysia, JB | F23: Own Quota | G23: 45680 | H23: 45680 | I23: ASP Jannah Wong | J23: {=MAX(COUNTIFS(Table1[Date of Departure], "<=" & _xlfn.SEQUENCE(Table1[[#This Row],[Date of Return]] - Table1[[#This Row],[Date of Departure]] + 1, , Table1[[#This Row],[Date of Departure]]), Table1[Date of Return], ">=" & _xlfn.SEQUENCE(Table1[[#This Row],[Date of Return]] - Table1[[#This Row],[Date of Departure]] + 1, , Table1[[#This Row],[Date of Departure]])))} -> 3 | K23: =IF(Table1[[#This Row],[Unit''s Leave Quota]]<=6, "Approved", "Quota Exceeded") -> Approved | M23: JB Day Trip, 1st quota
A24: 45656 | B24: Reg | C24: SSSgt | D24: Lim Rong Hoe | E24: Malaysia | F24: Own Quota | G24: 45673 | H24: 45675 | I24: ASP Christopher Tan | J24: {=MAX(COUNTIFS(Table1[Date of Departure], "<=" & _xlfn.SEQUENCE(Table1[[#This Row],[Date of Return]] - Table1[[#This Row],[Date of Departure]] + 1, , Table1[[#This Row],[Date of Departure]]), Table1[Date of Return], ">=" & _xlfn.SEQUENCE(Table1[[#This Row],[Date of Return]] - Table1[[#This Row],[Date of Departure]] + 1, , Table1[[#This Row],[Date of Departure]])))} -> 6 | K24: =IF(Table1[[#This Row],[Unit''s Leave Quota]]<=6, "Approved", "Quota Exceeded") -> Approved | M24: 16th Jan (using 3rd quota), 17th-18th Jan (using 4th quota)
A25: 45656 | B25: Reg | C25: SSSgt | D25: Lim Rong Hoe | E25: Malaysia | F25: Own Quota | G25: 45715 | H25: 45717 | I25: ASP Christopher Tan | J25: {=MAX(COUNTIFS(Table1[Date of Departure], "<=" & _xlfn.SEQUENCE(Table1[[#This Row],[Date of Return]] - Table1[[#This Row],[Date of Departure]] + 1, , Table1[[#This Row],[Date of Departure]]), Table1[Date of Return], ">=" & _xlfn.SEQUENCE(Table1[[#This Row],[Date of Return]] - Table1[[#This Row],[Date of Departure]] + 1, , Table1[[#This Row],[Date of Departure]])))} -> 3 | K25: =IF(Table1[[#This Row],[Unit''s Leave Quota]]<=6, "Approved", "Quota Exceeded") -> Approved | M25: 27th-28 Feb (using 2nd quota), 1st Mar (using 3rd quota)
A26: 45657 | B26: Reg | C26: SSSgt | D26: Lai Shang Yu | E26: Malaysia, JB | F26: Own Quota | G26: 45674 | H26: 45675 | I26: ASP Marah | J26: {=MAX(COUNTIFS(Table1[Date of Departure], "<=" & _xlfn.SEQUENCE(Table1[[#This Row],[Date of Return]] - Table1[[#This Row],[Date of Departure]] + 1, , Table1[[#This Row],[Date of Departure]]), Table1[Date of Return], ">=" & _xlfn.SEQUENCE(Table1[[#This Row],[Date of Return]] - Table1[[#This Row],[Date of Departure]] + 1, , Table1[[#This Row],[Date of Departure]])))} -> 6 | K26: =IF(Table1[[#This Row],[Unit''s Leave Quota]]<=6, "Approved", "Quota Exceeded") -> Approved | M26: 17-18(3rd quota used)
A27: 45657 | B27: Reg | C27: SSSgt | D27: Lai Shang Yu | E27: Malaysia, JB | F27: Own Quota | G27: 45694 | H27: 45698 | I27: ASP Tarmizi | J27: {=MAX(COUNTIFS(Table1[Date of Departure], "<=" & _xlfn.SEQUENCE(Table1[[#This Row],[Date of Return]] - Table1[[#This Row],[Date of Departure]] + 1, , Table1[[#This Row],[Date of Departure]]), Table1[Date of Return], ">=" & _xlfn.SEQUENCE(Table1[[#This Row],[Date of Return]] - Table1[[#This Row],[Date of Departure]] + 1, , Table1[[#This Row],[Date of Departure]])))} -> 4 | K27: =IF(Table1[[#This Row],[Unit''s Leave Quota]]<=6, "Approved", "Quota Exceeded") -> Approved | M27: 6-10(2nd quota used)
A28: 45657 | B28: Reg | C28: SSSgt | D28: Lai Shang Yu | E28: Malaysia, JB | F28: Own Quota | G28: 45710 | H28: 45711 | I28: ASP Tarmizi | J28: {=MAX(COUNTIFS(Table1[Date of Departure], "<=" & _xlfn.SEQUENCE(Table1[[#This Row],[Date of Return]] - Table1[[#This Row],[Date of Departure]] + 1, , Table1[[#This Row],[Date of Departure]]), Table1[Date of Return], ">=" & _xlfn.SEQUENCE(Table1[[#This Row],[Date of Return]] - Table1[[#This Row],[Date of Departure]] + 1, , Table1[[#This Row],[Date of Departure]])))} -> 6 | K28: =IF(Table1[[#This Row],[Unit''s Leave Quota]]<=6, "Approved", "Quota Exceeded") -> Approved | M28: 22-23(3rd quota used)
A29: 45657 | B29: Reg | C29: SSSgt | D29: Lai Shang Yu | E29: Malaysia, Malacca | F29: Own Quota | G29: 45721 | H29: 45725 | I29: ASP Tarmizi | J29: {=MAX(COUNTIFS(Table1[Date of Departure], "<=" & _xlfn.SEQUENCE(Table1[[#This Row],[Date of Return]] - Table1[[#This Row],[Date of Departure]] + 1, , Table1[[#This Row],[Date of Departure]]), Table1[Date of Return], ">=" & _xlfn.SEQUENCE(Table1[[#This Row],[Date of Return]] - Table1[[#This Row],[Date of Departure]] + 1, , Table1[[#This Row],[Date of Departure]])))} -> 6 | K29: =IF(Table1[[#This Row],[Unit''s Leave Quota]]<=6, "Approved", "Quota Exceeded") -> Approved | M29: 5-9 Mar(2nd quota used)
A30: 45660 | B30: Reg | C30: Sgt(3) | D30: M Faiz Fazely | E30: Malaysia | F30: Own Quota | G30: 45663 | H30: 45663 | I30: ASP Christopher Tan | J30: {=MAX(COUNTIFS(Table1[Date of Departure], "<=" & _xlfn.SEQUENCE(Table1[[#This Row],[Date of Return]] - Table1[[#This Row],[Date of Departure]] + 1, , Table1[[#This Row],[Date of Departure]]), Table1[Date of Return], ">=" & _xlfn.SEQUENCE(Table1[[#This Row],[Date of Return]] - Table1[[#This Row],[Date of Departure]] + 1, , Table1[[#This Row],[Date of Departure]])))} -> 4 | K30: =IF(Table1[[#This Row],[Unit''s Leave Quota]]<=6, "Approved", "Quota Exceeded") -> Approved
A31: 45660 | B31: Reg | C31: SSSgt | D31: Chionh Jia Ru, Jared | E31: Malaysia, JB | F31: Own Quota | G31: 45672 | H31: 45672 | I31: ASP Darrick Chew | J31: {=MAX(COUNTIFS(Table1[Date of Departure], "<=" & _xlfn.SEQUENCE(Table1[[#This Row],[Date of Return]] - Table1[[#This Row],[Date of Departure]] + 1, , Table1[[#This Row],[Date of Departure]]), Table1[Date of Return], ">=" & _xlfn.SEQUENCE(Table1[[#This Row],[Date of Return]] - Table1[[#This Row],[Date of Departure]] + 1, , Table1[[#This Row],[Date of Departure]])))} -> 4 | K31: =IF(Table1[[#This Row],[Unit''s Leave Quota]]<=6, "Approved", "Quota Exceeded") -> Approved
A32: 45660 | B32: Reg | C32: Sgt(3) | D32: Wong Jia Wen, Jovi | E32: Japan | F32: Own Quota | G32: 45824 | H32: 45838 | I32: ASP Darrick | J32: {=MAX(COUNTIFS(Table1[Date of Departure], "<=" & _xlfn.SEQUENCE(Table1[[#This Row],[Date of Return]] - Table1[[#This Row],[Date of Departure]] + 1, , Table1[[#This Row],[Date of Departure]]), Table1[Date of Return], ">=" & _xlfn.SEQUENCE(Table1[[#This Row],[Date of Return]] - Table1[[#This Row],[Date of Departure]] + 1, , Table1[[#This Row],[Date of Departure]])))} -> 6 | K32: =IF(Table1[[#This Row],[Unit''s Leave Quota]]<=6, "Approved", "Quota Exceeded") -> Approved
A33: 45663 | B33: Reg | C33: SSSgt | D33: Faizal Minggu | E33: Malaysia, JB | F33: Own Quota | G33: 45668 | H33: 45668 | I33: ASP Jannah Wong | J33: {=MAX(COUNTIFS(Table1[Date of Departure], "<=" & _xlfn.SEQUENCE(Table1[[#This Row],[Date of Return]] - Table1[[#This Row],[Date of Departure]] + 1, , Table1[[#This Row],[Date of Departure]]), Table1[Date of Return], ">=" & _xlfn.SEQUENCE(Table1[[#This Row],[Date of Return]] - Table1[[#This Row],[Date of Departure]] + 1, , Table1[[#This Row],[Date of Departure]])))} -> 6 | K33: =IF(Table1[[#This Row],[Unit''s Leave Quota]]<=6, "Approved", "Quota Exceeded") -> Approved | M33: JB Day trip, 6th Quota
A34: 45663 | B34: Reg | C34: SSSgt | D34: Faizal Minggu | E34: Malaysia, JB | F34: Own Quota | G34: 45672 | H34: 45672 | I34: ASP Jannah Wong | J34: {=MAX(COUNTIFS(Table1[Date of Departure], "<=" & _xlfn.SEQUENCE(Table1[[#This Row],[Date of Return]] - Table1[[#This Row],[Date of Departure]] + 1, , Table1[[#This Row],[Date of Departure]]), Table1[Date of Return], ">=" & _xlfn.SEQUENCE(Table1[[#This Row],[Date of Return]] - Table1[[#This Row],[Date of Departure]] + 1, , Table1[[#This Row],[Date of Departure]])))} -> 4 | K34: =IF(Table1[[#This Row],[Unit''s Leave Quota]]<=6, "Approved", "Quota Exceeded") -> Approved | M34: JB Day trip, 3rd Quota
A35: 45663 | B35: Reg | C35: SSSgt | D35: Faizal Minggu | E35: Malaysia, JB | F35: Own Quota | G35: 45680 | H35: 45680 | I35: ASP Jannah Wong | J35: {=MAX(COUNTIFS(Table1[Date of Departure], "<=" & _xlfn.SEQUENCE(Table1[[#This Row],[Date of Return]] - Table1[[#This Row],[Date of Departure]] + 1, , Table1[[#This Row],[Date of Departure]]), Table1[Date of Return], ">=" & _xlfn.SEQUENCE(Table1[[#This Row],[Date of Return]] - Table1[[#This Row],[Date of Departure]] + 1, , Table1[[#This Row],[Date of Departure]])))} -> 3 | K35: =IF(Table1[[#This Row],[Unit''s Leave Quota]]<=6, "Approved", "Quota Exceeded") -> Approved | M35: JB Day Trip, 2nd quota
A36: 45663 | B36: Reg | C36: SSSgt | D36: Faizal Minggu | E36: Malaysia, JB | F36: Own Quota | G36: 45685 | H36: 45685 | I36: ASP Jannah Wong | J36: {=MAX(COUNTIFS(Table1[Date of Departure], "<=" & _xlfn.SEQUENCE(Table1[[#This Row],[Date of Return]] - Table1[[#This Row],[Date of Departure]] + 1, , Table1[[#This Row],[Date of Departure]]), Table1[Date of Return], ">=" & _xlfn.SEQUENCE(Table1[[#This Row],[Date of Return]] - Table1[[#This Row],[Date of Departure]] + 1, , Table1[[#This Row],[Date of Departure]])))} -> 1 | K36: =IF(Table1[[#This Row],[Unit''s Leave Quota]]<=6, "Approved", "Quota Exceeded") -> Approved | M36: JB Day Trip, 0th quota
A37: 45663 | B37: Reg | C37: Sgt(3) | D37: Alvin Wee Han Kuang | E37: Bangkok | F37: Own Quota | G37: 45800 | H37: 45804 | I37: ASP Jannah Wong | J37: {=MAX(COUNTIFS(Table1[Date of Departure], "<=" & _xlfn.SEQUENCE(Table1[[#This Row],[Date of Return]] - Table1[[#This Row],[Date of Departure]] + 1, , Table1[[#This Row],[Date of Departure]]), Table1[Date of Return], ">=" & _xlfn.SEQUENCE(Table1[[#This Row],[Date of Return]] - Table1[[#This Row],[Date of Departure]] + 1, , Table1[[#This Row],[Date of Departure]])))} -> 6 | K37: =IF(Table1[[#This Row],[Unit''s Leave Quota]]<=6, "Approved", "Quota Exceeded") -> Approved
A38: 45664 | B38: Reg | C38: SI | D38: Mohammad Rohaizat Bin Abu Bakar | E38: Malaysia, JB | F38: Own Quota | G38: 45664 | H38: 45665 | I38: DSP Idil | J38: {=MAX(COUNTIFS(Table1[Date of Departure], "<=" & _xlfn.SEQUENCE(Table1[[#This Row],[Date of Return]] - Table1[[#This Row],[Date of Departure]] + 1, , Table1[[#This Row],[Date of Departure]]), Table1[Date of Return], ">=" & _xlfn.SEQUENCE(Table1[[#This Row],[Date of Return]] - Table1[[#This Row],[Date of Departure]] + 1, , Table1[[#This Row],[Date of Departure]])))} -> 6 | K38: =IF(Table1[[#This Row],[Unit''s Leave Quota]]<=6, "Approved", "Quota Exceeded") -> Approved
A39: 45666 | B39: Reg | C39: Sgt(3) | D39: Aelma Sheiqa Binte Mohamed Padillah | E39: Thailand | F39: Own Quota | G39: 45779 | H39: 45782 | I39: ASP Darrick | J39: {=MAX(COUNTIFS(Table1[Date of Departure], "<=" & _xlfn.SEQUENCE(Table1[[#This Row],[Date of Return]] - Table1[[#This Row],[Date of Departure]] + 1, , Table1[[#This Row],[Date of Departure]]), Table1[Date of Return], ">=" & _xlfn.SEQUENCE(Table1[[#This Row],[Date of Return]] - Table1[[#This Row],[Date of Departure]] + 1, , Table1[[#This Row],[Date of Departure]])))} -> 3 | K39: =IF(Table1[[#This Row],[Unit''s Leave Quota]]<=6, "Approved", "Quota Exceeded") -> Approved | M39: (Cancelled due to GE)
A40: 45671 | B40: Reg | C40: SI | D40: Mohammad Rohaizat Bin Abu Bakar | E40: Malaysia, JB | F40: Own Quota | G40: 45675 | H40: 45675 | I40: ASP Christopher Tan | J40: {=MAX(COUNTIFS(Table1[Date of Departure], "<=" & _xlfn.SEQUENCE(Table1[[#This Row],[Date of Return]] - Table1[[#This Row],[Date of Departure]] + 1, , Table1[[#This Row],[Date of Departure]]), Table1[Date of Return], ">=" & _xlfn.SEQUENCE(Table1[[#This Row],[Date of Return]] - Table1[[#This Row],[Date of Departure]] + 1, , Table1[[#This Row],[Date of Departure]])))} -> 6 | K40: =IF(Table1[[#This Row],[Unit''s Leave Quota]]<=6, "Approved", "Quota Exceeded") -> Approved
...

Sheet Ops
A1: {=_xlfn.VSTACK(Table1[#Headers], _xlfn._xlws.FILTER(Table1[], Table1[Unit]="Ops"))} -> Date of Submmision | B1: Scheme | C1: Rank | D1: Name of Officer applying for leave (Full Name) | E1: Country of Travel Country, State | F1: Own Quota/ Borrowed Quota | G1: Date of Departure | H1: Date of Return | I1: Leave Approving Officer in HRP | J1: Unit's Leave Quota | K1: OC Approved? | L1: Unit | M1: Remarks
A2: 46038 | B2: Reg | C2: SI | D2: Zainal Abideen | E2: Malaysia, JB | F2: Own Quota | G2: 46024 | H2: 46025 | I2: Marah Ishraf | J2: 6 | K2: Approved | L2: Ops | M2: Nil
A3: 46040 | B3: Reg | C3: Sgt(3) | D3: Krishna S/O Jeyaseelan | E3: JB | F3: Own Quota | G3: 46024 | H3: 46025 | I3: Marah Ishraf | J3: 6 | K3: Approved | L3: Ops | M3: Nil

Sheet Daily Slots
A1: Date | B1: Quota Used | C1: Quota Bal | D1: Status | E1: Review Latest Submission | F1: Total Slots: | G1: 6
A2: 46023 | B2: =COUNTIFS('2025'!G:G,"<="&A2,'2025'!H:H,">="&A2) -> 5 | C2: =$G$1-B2 -> 1 | D2: =IF(C2<0,"OVERBOOKED",IF(C2=0,"FULL","AVAILABLE")) -> AVAILABLE | E2: {=IF(D2="OVERBOOKED", HYPERLINK("#'2025'!A"& LOOKUP(2,1/(('2025'!A$2:A$1000= _xlfn.MAXIFS('2025'!A:A,'2025'!G:G,"<="&A2,'2025'!H:H,">="&A2)) *('2025'!G$2:G$1000<=A2) *('2025'!H$2:H$1000>=A2)), ROW('2025'!A$2:A$1000) ), "Review" ), "")}
A3: =A2+1 -> 46024 | B3: =COUNTIFS('2025'!G:G,"<="&A3,'2025'!H:H,">="&A3) -> 4 | C3: =$G$1-B3 -> 2 | D3: =IF(C3<0,"OVERBOOKED",IF(C3=0,"FULL","AVAILABLE")) -> AVAILABLE | E3: {=IF(D3="OVERBOOKED", HYPERLINK("#'2025'!A"& LOOKUP(2,1/(('2025'!A$2:A$1000= _xlfn.MAXIFS('2025'!A:A,'2025'!G:G,"<="&A3,'2025'!H:H,">="&A3)) *('2025'!G$2:G$1000<=A3) *('2025'!H$2:H$1000>=A3)), ROW('2025'!A$2:A$1000) ), "Review" ), "")}
A4: =A3+1 -> 46025 | B4: =COUNTIFS('2025'!G:G,"<="&A4,'2025'!H:H,">="&A4) -> 6 | C4: =$G$1-B4 -> 0 | D4: =IF(C4<0,"OVERBOOKED",IF(C4=0,"FULL","AVAILABLE")) -> FULL | E4: {=IF(D4="OVERBOOKED", HYPERLINK("#'2025'!A"& LOOKUP(2,1/(('2025'!A$2:A$1000= _xlfn.MAXIFS('2025'!A:A,'2025'!G:G,"<="&A4,'2025'!H:H,">="&A4)) *('2025'!G$2:G$1000<=A4) *('2025'!H$2:H$1000>=A4)), ROW('2025'!A$2:A$1000) ), "Review" ), "")}
A5: =A4+1 -> 46026 | B5: =COUNTIFS('2025'!G:G,"<="&A5,'2025'!H:H,">="&A5) -> 3 | C5: =$G$1-B5 -> 3 | D5: =IF(C5<0,"OVERBOOKED",IF(C5=0,"FULL","AVAILABLE")) -> AVAILABLE | E5: {=IF(D5="OVERBOOKED", HYPERLINK("#'2025'!A"& LOOKUP(2,1/(('2025'!A$2:A$1000= _xlfn.MAXIFS('2025'!A:A,'2025'!G:G,"<="&A5,'2025'!H:H,">="&A5)) *('2025'!G$2:G$1000<=A5) *('2025'!H$2:H$1000>=A5)), ROW('2025'!A$2:A$1000) ), "Review" ), "")}
A6: =A5+1 -> 46027 | B6: =COUNTIFS('2025'!G:G,"<="&A6,'2025'!H:H,">="&A6) -> 1 | C6: =$G$1-B6 -> 5 | D6: =IF(C6<0,"OVERBOOKED",IF(C6=0,"FULL","AVAILABLE")) -> AVAILABLE | E6: {=IF(D6="OVERBOOKED", HYPERLINK("#'2025'!A"& LOOKUP(2,1/(('2025'!A$2:A$1000= _xlfn.MAXIFS('2025'!A:A,'2025'!G:G,"<="&A6,'2025'!H:H,">="&A6)) *('2025'!G$2:G$1000<=A6) *('2025'!H$2:H$1000>=A6)), ROW('2025'!A$2:A$1000) ), "Review" ), "")}
A7: =A6+1 -> 46028 | B7: =COUNTIFS('2025'!G:G,"<="&A7,'2025'!H:H,">="&A7) -> 2 | C7: =$G$1-B7 -> 4 | D7: =IF(C7<0,"OVERBOOKED",IF(C7=0,"FULL","AVAILABLE")) -> AVAILABLE | E7: {=IF(D7="OVERBOOKED", HYPERLINK("#'2025'!A"& LOOKUP(2,1/(('2025'!A$2:A$1000= _xlfn.MAXIFS('2025'!A:A,'2025'!G:G,"<="&A7,'2025'!H:H,">="&A7)) *('2025'!G$2:G$1000<=A7) *('2025'!H$2:H$1000>=A7)), ROW('2025'!A$2:A$1000) ), "Review" ), "")}
A8: =A7+1 -> 46029 | B8: =COUNTIFS('2025'!G:G,"<="&A8,'2025'!H:H,">="&A8) -> 5 | C8: =$G$1-B8 -> 1 | D8: =IF(C8<0,"OVERBOOKED",IF(C8=0,"FULL","AVAILABLE")) -> AVAILABLE | E8: {=IF(D8="OVERBOOKED", HYPERLINK("#'2025'!A"& LOOKUP(2,1/(('2025'!A$2:A$1000= _xlfn.MAXIFS('2025'!A:A,'2025'!G:G,"<="&A8,'2025'!H:H,">="&A8)) *('2025'!G$2:G$1000<=A8) *('2025'!H$2:H$1000>=A8)), ROW('2025'!A$2:A$1000) ), "Review" ), "")}
A9: =A8+1 -> 46030 | B9: =COUNTIFS('2025'!G:G,"<="&A9,'2025'!H:H,">="&A9) -> 4 | C9: =$G$1-B9 -> 2 | D9: =IF(C9<0,"OVERBOOKED",IF(C9=0,"FULL","AVAILABLE")) -> AVAILABLE | E9: {=IF(D9="OVERBOOKED", HYPERLINK("#'2025'!A"& LOOKUP(2,1/(('2025'!A$2:A$1000= _xlfn.MAXIFS('2025'!A:A,'2025'!G:G,"<="&A9,'2025'!H:H,">="&A9)) *('2025'!G$2:G$1000<=A9) *('2025'!H$2:H$1000>=A9)), ROW('2025'!A$2:A$1000) ), "Review" ), "")}
A10: =A9+1 -> 46031 | B10: =COUNTIFS('2025'!G:G,"<="&A10,'2025'!H:H,">="&A10) -> 4 | C10: =$G$1-B10 -> 2 | D10: =IF(C10<0,"OVERBOOKED",IF(C10=0,"FULL","AVAILABLE")) -> AVAILABLE | E10: {=IF(D10="OVERBOOKED", HYPERLINK("#'2025'!A"& LOOKUP(2,1/(('2025'!A$2:A$1000= _xlfn.MAXIFS('2025'!A:A,'2025'!G:G,"<="&A10,'2025'!H:H,">="&A10)) *('2025'!G$2:G$1000<=A10) *('2025'!H$2:H$1000>=A10)), ROW('2025'!A$2:A$1000) ), "Review" ), "")}
A11: =A10+1 -> 46032 | B11: =COUNTIFS('2025'!G:G,"<="&A11,'2025'!H:H,">="&A11) -> 6 | C11: =$G$1-B11 -> 0 | D11: =IF(C11<0,"OVERBOOKED",IF(C11=0,"FULL","AVAILABLE")) -> FULL | E11: {=IF(D11="OVERBOOKED", HYPERLINK("#'2025'!A"& LOOKUP(2,1/(('2025'!A$2:A$1000= _xlfn.MAXIFS('2025'!A:A,'2025'!G:G,"<="&A11,'2025'!H:H,">="&A11)) *('2025'!G$2:G$1000<=A11) *('2025'!H$2:H$1000>=A11)), ROW('2025'!A$2:A$1000) ), "Review" ), "")}
A12: =A11+1 -> 46033 | B12: =COUNTIFS('2025'!G:G,"<="&A12,'2025'!H:H,">="&A12) -> 4 | C12: =$G$1-B12 -> 2 | D12: =IF(C12<0,"OVERBOOKED",IF(C12=0,"FULL","AVAILABLE")) -> AVAILABLE | E12: {=IF(D12="OVERBOOKED", HYPERLINK("#'2025'!A"& LOOKUP(2,1/(('2025'!A$2:A$1000= _xlfn.MAXIFS('2025'!A:A,'2025'!G:G,"<="&A12,'2025'!H:H,">="&A12)) *('2025'!G$2:G$1000<=A12) *('2025'!H$2:H$1000>=A12)), ROW('2025'!A$2:A$1000) ), "Review" ), "")}
A13: =A12+1 -> 46034 | B13: =COUNTIFS('2025'!G:G,"<="&A13,'2025'!H:H,">="&A13) -> 3 | C13: =$G$1-B13 -> 3 | D13: =IF(C13<0,"OVERBOOKED",IF(C13=0,"FULL","AVAILABLE")) -> AVAILABLE
A14: =A13+1 -> 46035 | B14: =COUNTIFS('2025'!G:G,"<="&A14,'2025'!H:H,">="&A14) -> 2 | C14: =$G$1-B14 -> 4 | D14: =IF(C14<0,"OVERBOOKED",IF(C14=0,"FULL","AVAILABLE")) -> AVAILABLE
A15: =A14+1 -> 46036 | B15: =COUNTIFS('2025'!G:G,"<="&A15,'2025'!H:H,">="&A15) -> 3 | C15: =$G$1-B15 -> 3 | D15: =IF(C15<0,"OVERBOOKED",IF(C15=0,"FULL","AVAILABLE")) -> AVAILABLE
A16: =A15+1 -> 46037 | B16: =COUNTIFS('2025'!G:G,"<="&A16,'2025'!H:H,">="&A16) -> 2 | C16: =$G$1-B16 -> 4 | D16: =IF(C16<0,"OVERBOOKED",IF(C16=0,"FULL","AVAILABLE")) -> AVAILABLE
A17: =A16+1 -> 46038 | B17: =COUNTIFS('2025'!G:G,"<="&A17,'2025'!H:H,">="&A17) -> 4 | C17: =$G$1-B17 -> 2 | D17: =IF(C17<0,"OVERBOOKED",IF(C17=0,"FULL","AVAILABLE")) -> AVAILABLE
A18: =A17+1 -> 46039 | B18: =COUNTIFS('2025'!G:G,"<="&A18,'2025'!H:H,">="&A18) -> 4 | C18: =$G$1-B18 -> 2 | D18: =IF(C18<0,"OVERBOOKED",IF(C18=0,"FULL","AVAILABLE")) -> AVAILABLE
A19: =A18+1 -> 46040 | B19: =COUNTIFS('2025'!G:G,"<="&A19,'2025'!H:H,">="&A19) -> 3 | C19: =$G$1-B19 -> 3 | D19: =IF(C19<0,"OVERBOOKED",IF(C19=0,"FULL","AVAILABLE")) -> AVAILABLE
A20: =A19+1 -> 46041 | B20: =COUNTIFS('2025'!G:G,"<="&A20,'2025'!H:H,">="&A20) -> 2 | C20: =$G$1-B20 -> 4 | D20: =IF(C20<0,"OVERBOOKED",IF(C20=0,"FULL","AVAILABLE")) -> AVAILABLE
A21: =A20+1 -> 46042 | B21: =COUNTIFS('2025'!G:G,"<="&A21,'2025'!H:H,">="&A21) -> 2 | C21: =$G$1-B21 -> 4 | D21: =IF(C21<0,"OVERBOOKED",IF(C21=0,"FULL","AVAILABLE")) -> AVAILABLE
A22: =A21+1 -> 46043 | B22: =COUNTIFS('2025'!G:G,"<="&A22,'2025'!H:H,">="&A22) -> 1 | C22: =$G$1-B22 -> 5 | D22: =IF(C22<0,"OVERBOOKED",IF(C22=0,"FULL","AVAILABLE")) -> AVAILABLE
A23: =A22+1 -> 46044 | B23: =COUNTIFS('2025'!G:G,"<="&A23,'2025'!H:H,">="&A23) -> 3 | C23: =$G$1-B23 -> 3 | D23: =IF(C23<0,"OVERBOOKED",IF(C23=0,"FULL","AVAILABLE")) -> AVAILABLE
A24: =A23+1 -> 46045 | B24: =COUNTIFS('2025'!G:G,"<="&A24,'2025'!H:H,">="&A24) -> 2 | C24: =$G$1-B24 -> 4 | D24: =IF(C24<0,"OVERBOOKED",IF(C24=0,"FULL","AVAILABLE")) -> AVAILABLE
... A368: =A367+1 -> 46389 | B368: =COUNTIFS('2025'!G:G,"<="&A368,'2025'!H:H,">="&A368) -> 1 | C368: =$G$1-B368 -> 5 | D368: =IF(C368<0,"OVERBOOKED",IF(C368=0,"FULL","AVAILABLE")) -> AVAILABLE

Sheet Code
A1: =MAX(COUNTIFS([Date of Departure], "<=" & SEQUENCE([@Date of Return] - [@Date of Departure] + 1, , [@Date of Departure]), [Date of Return], ">=" & SEQUENCE([@Date of Return] - [@Date of Departure] + 1, , [@Date of Departure])))

Sheet Output
A1: Date | B1: Quota Bal
A2: 46023 | B2: 2
A3: 46024 | B3: 4
A4: 46025 | B4: 2
A5: 46026 | B5: 3
A6: 46027 | B6: 5
A7: 46028 | B7: 4
A8: 46029 | B8: -2
A9: 46030 | B9: 1
A10: 46031 | B10: 1
A11: 46032 | B11: -1
A12: 46033 | B12: 1
A13: 46034 | B13: 2
... A368: 46389 | B368: 5
